Workbook

Sheet 目录
H4: 明日之星华南价格表入仓执行日期2025/1/27
B5: 浙江明日之星供应链（深圳分公司）价格表一览表
B6: 区域 | C6: 省份 | D6: 城市 | E6: 仓库地址/联系人 | K6: 备注
B7: 华东仓 | C7: 浙江 | D7: 义乌(明星仓1号仓) | E7: 义乌仓：诸暨市安华镇万宏路2号万纬绍兴诸暨园区一楼2号库2分区2-06号门收货 联系方式：18749171088 程主管 | K7: 未贴标货物入库
D8: 义乌(明星仓2号仓) | E8: 义乌仓：诸暨市安华镇万宏路2号万纬绍兴诸暨园区一楼2号库2分区2-06号门收货 联系方式：18749171088 程主管 | K8: 已贴标货物入库
C9: 福建 | D9: 泉州(明星仓3号仓) | E9: 泉州仓：福建省泉州市晋江市法藏路11号（万纬泉州晋江冷链物流园） 联系方式：13110972302 张经理 | K9: 已贴标货物入库
D10: 厦门（明星仓7号仓） | E10: 厦门仓：厦门市海沧区港南路336号之30-31号中远海运仓库 联系方式：18060171990 张经理 | K10: 已贴标货物入库
B11: 华南仓 | C11: 广东 | D11: 东莞(明星仓5号仓) | E11: 东莞仓： 东莞市凤岗镇三联村三联路19号 (进园区左手边) 联系方式：17607947904 席经理 | K11: 已贴标货物入库
D12: 福永（明星仓6号仓） | E12: 深圳市宝安区沙井街道和旺一路2号仓库3栋一层（导航：和旺产业园）联系方式: 15096566889 曹经理 | K12: 已贴标货物入库
B14: MRZX-赔偿说明及发货须知 | C14: 点击进入
B15: 明日之星下单渠道明细归类 | C15: 点击进入
B16: MXD-美国华南海派全渠道 | C16: 点击进入报价 | D16: 2026-1-27价格更新 | E16: 分别14/16/18/23天左右提取 | F16: CLX/MAX/EXX/ZIM/OA | H16: 7截3开/7截4开 | I16: 7截3开/7截4开 | J16: 体积/6000
B17: MXD-华南明星达14T卡派 | C17: 点击进入报价 | D17: 2026-1-27价格更新 | E17: 性价比高/16天左右签收 | F17: CLX | H17: 7截3开 | I17: 7截3开 | J17: 体积/6000
B18: MXD-华南明星达16T卡派 | C18: 点击进入报价 | D18: 2026-1-27价格更新 | E18: 性价比高/18天左右签收 | F18: MAX | H18: 7截4开 | I18: 7截4开 | J18: 体积/6000
B19: MXD-华南明星达18T卡派 | C19: 点击进入报价 | D19: 2026-1-27价格更新 | E19: 性价比高/20天左右签收 | F19: EXX/ZEX/HDS3 | H19: 7截4开 | I19: 7截4开 | J19: 体积/6000
B20: MXD-华南明星达20T卡派 | C20: 点击进入报价 | D20: 2026-1-27价格更新 | E20: 性价比高/25天左右签收 | F20: HDS3 | H20: 7截4开 | I20: 7截4开 | J20: 体积/6000
B21: MXD-华南OA普船卡派 | C21: 点击进入报价 | D21: 2026-1-27价格更新 | E21: 性价比高/28天左右签收 | F21: 精品OA-SEA/SEA3 | H21: 7截4开 | I21: 7截4开 | J21: 体积/6000
B22: MXD-华南特惠普船卡派 | C22: 点击进入报价 | D22: 2026-1-27价格更新 | E22: 性价比高/30天左右签收 | F22: SML/HMM/WHL/YMM/TSL/SLS/ONE/CUL统配 | H22: 7截6开 | I22: 2截6开 | J22: 体积/6000
B23: MXD-华南西雅图普船卡派 | C23: 点击进入报价 | D23: 2026-1-27价格更新 | E23: 性价比高/35天左右签收 | F23: OA/SML | H23: 7截2开 | I23: 6截2开 | J23: 体积/6000
B24: MXD-华南奥克兰普船卡派 | C24: 点击进入报价 | D24: 2026-1-27价格更新 | E24: 性价比高/30天左右签收 | F24: EXX航线/CMA/EMC | H24: 7截4开 | I24: 1截4开 | J24: 体积/6000
B25: MXD-华南芝加哥普船卡派 | C25: 点击进入报价 | D25: 2026-1-27价格更新 | E25: 性价比高/35天左右签收 | F25: EXX航线/OA/SML | H25: 7截4开 | I25: 6截4开 | J25: 体积/6000
B26: MXD-华南休斯顿普船卡派 | C26: 点击进入报价 | D26: 2026-1-27价格更新 | E26: 性价比高/35天左右签收 | F26: COSCO | H26: 7截2开 | I26: 6截2开 | J26: 体积/6000
B27: MXD-华南萨凡纳普船卡派 | C27: 点击进入报价 | D27: 2026-1-27价格更新 | E27: 性价比高/40天左右签收 | F27: OA/SML | H27: 7截2开 | I27: 6截2开 | J27: 体积/6000
... B33: MXD-华南全美商私卡 | C33: 点击进入报价 | D33: 2026-1-27价格更新 | E33: 性价比高16/18/20/25/30天左右签收 | F33: CLX/MAX/EXX/ZIM/HDS3/OA | H33: 7截2开 | I33: 5截2开 | J33: 体积/6000
B34: 美国亚马逊常见偏远地址 | C34: 点击进入
B35: 美国海运偏远邮编 | C35: 点击进入
B36: 夏威夷&阿拉斯加邮编无服务 | C36: 点击进入
B37: 美国亚马逊仓库 | C37: 点击进入
B38: 发票模版 | C38: 点击进入

Sheet 价格查询表
E2: =目录!H4 -> 明日之星华南价格表入仓执行日期2025/1/27
B3: 请输入查询仓库
B4: iust
B6: 渠道 | C6: 小货价 | D6: 大货价 | E6: 义乌按方 | F6: 起收重量 | G6: 时效
B7: 华南明星达14T卡派 | C7: {=IFERROR(VLOOKUP("*"&$B$4&"*",INDIRECT("'"&B7&"'!B:K"),{2,3,4,5,6},0),"无")} -> 无
B8: 华南明星达16T卡派 | C8: {=IFERROR(VLOOKUP("*"&$B$4&"*",INDIRECT("'"&B8&"'!B:K"),{2,3,4,5,6},0),"无")} -> 无
B9: 华南明星达18T卡派 | C9: {=IFERROR(VLOOKUP("*"&$B$4&"*",INDIRECT("'"&B9&"'!c:K"),{2,3,4,5,6},0),"无")} -> 10 | D9: 9 | E9: 1800 | F9: 12KG+/1CBM+ | G9: 25-29天左右签收
B10: 华南明星达20T卡派 | C10: {=IFERROR(VLOOKUP("*"&$B$4&"*",INDIRECT("'"&B10&"'!c:K"),{2,3,4,5,6},0),"无")} -> 9.3 | D10: 8.3 | E10: 1660 | F10: 12KG+/1CBM+ | G10: 25-29天左右签收
B11: 华南OA普船卡派 | C11: {=IFERROR(VLOOKUP("*"&$B$4&"*",INDIRECT("'"&B11&"'!c18:K100"),{2,3,4,5,6},0),"无")} -> 8.6 | D11: 7.6 | E11: 1520 | F11: 12KG+/1CBM+ | G11: 27-35天签收
B12: 华南OA卡派直送 | C12: {=IFERROR(VLOOKUP("*"&$B$4&"*",INDIRECT("'"&B11&"'!c11:K12"),{2,3,4,5,6},0),"无")} -> 无
B13: 华南特惠普船卡派 | C13: {=IFERROR(VLOOKUP("*"&$B$4&"*",INDIRECT("'"&B13&"'!C15:K53"),{2,3,4,5,6},0),"无")} -> 8.3 | D13: 7.3 | E13: 1460 | F13: 12KG+/1CBM+ | G13: 27-36天左右签收
B14: 华南特惠普船直送卡派 | C14: {=IFERROR(VLOOKUP("*"&$B$4&"*",INDIRECT("'"&B13&"'!C11:K112"),{2,3,4,5,6},0),"无")} -> 8.3 | D14: 7.3 | E14: 1460 | F14: 12KG+/1CBM+ | G14: 27-36天左右签收
B15: 华南奥克兰普船卡派 | C15: {=IFERROR(VLOOKUP("*"&$B$4&"*",INDIRECT("'"&B15&"'!B:P"),{3,4,5,6,6},0),"无")} -> 无
B16: 华南奥克兰直送卡派 | C16: {=IFERROR(VLOOKUP("*"&$B$4&"*",INDIRECT("'"&B15&"'!C:P"),{3,4,5,6,7},0),"无")} -> 无
B17: 华南芝加哥普船卡派 | C17: {=IFERROR(VLOOKUP("*"&$B$4&"*",INDIRECT("'"&B17&"'!C11:P100"),{2,3,4,5,6},0),"无")} -> 无
B18: 华南芝加哥普船直送卡派 | C18: {=IFERROR(VLOOKUP("*"&$B$4&"*",INDIRECT("'"&B17&"'!C9:P10"),{2,3,4,5,6},0),"无")} -> 无
B19: 华南纽约海铁卡派 | C19: {=IFERROR(VLOOKUP("*"&$B$4&"*",INDIRECT("'"&B19&"'!B:K"),{2,3,4,5,6},0),"无")} -> 10 | D19: 9 | E19: 1800 | F19: 12kg+/1CBM | G19: 25-30天左右签收
B20: 华南纽约普船卡派 | C20: {=IFERROR(VLOOKUP("*"&$B$4&"*",INDIRECT("'"&B20&"'!B:K"),{2,3,4,5,6},0),"无")} -> 6.4 | D20: 5.4 | E20: 1080 | F20: 12kg+/1CBM | G20: 40-45天左右签收
B21: 华南纽约经济普船卡派 | C21: {=IFERROR(VLOOKUP("*"&$B$4&"*",INDIRECT("'"&B21&"'!B:K"),{2,3,4,5,6},0),"无")} -> 6.3 | D21: 5.3 | E21: 1060 | F21: 12kg+/1CBM | G21: 42-48天左右签收
B22: 华南萨凡纳普船卡派 | C22: {=IFERROR(VLOOKUP("*"&$B$4&"*",INDIRECT("'"&B22&"'!B:K"),{2,3,4,5,6},0),"无")} -> 无
B23: 华南休斯顿普船卡派 | C23: {=IFERROR(VLOOKUP("*"&$B$4&"*",INDIRECT("'"&B23&"'!C:K"),{2,3,4,5,5},0),"无")} -> 无
B24: 华南西雅图普船卡派 | C24: {=IFERROR(VLOOKUP("*"&$B$4&"*",INDIRECT("'"&B24&"'!B:K"),{2,3,4,5,6},0),"无")} -> 无

Sheet 船期表
A1: 浙江明日之星供应链管理有限公司(深圳分公司）
A2: 美线船期计划表(预计船期，请以实际开船到港时间为准）
K3: =目录!H4 -> 明日之星华南价格表入仓执行日期2025/1/27
A5: 产品渠道 | B5: 船公司 | C5: 航线 | D5: 船名航次 | E5: 始发港 | F5: 目的港 | G5: ETD船期 | H5: ETA时间 | I5: 航程 | J5: 到货日期 | K5: 下一水预配船期 | L5: 报关行信息
A6: 华南-明星达卡派14T/海派14T | B6: 美森 | C6: CLX | D6: KAIMANA HILA 070E | E6: 宁波 | F6: 长滩 | G6: 46055 | H6: 46068 | I6: 11 | J6: 46053 | K6: LURLINE 097E 预计开船时间 2-9 | L6: 义乌市乐通报关代理有限公司 海关代码331898008Q
A7: 华南-明星达海卡 16T/海派16T | B7: 美森 | C7: MAX | D7: MATSON MAUI 035E | E7: 宁波 | F7: 长滩 | G7: 46056 | H7: 46069 | I7: 11 | J7: 46053 | K7: MATSON LANAI 052E 预计开船时间 2-10 | L7: 义乌市乐通报关代理有限公司 海关代码331898008Q
A8: 华南-明星达18T/海派18T | B8: 以星 | C8: ZEX | D8: COLORADO 14E | E8: 盐田 | F8: 洛杉矶 | G8: 46057 | H8: 46070 | I8: 12.5 | J8: 46054 | K8: ZIM MOONSTONE5E 预计开船时间 2-11 | L8: 深圳市一路通达报关服务有限公司 海关代码4403980A0V
B9: 合德快提 | C9: HDS3 | D9: PORTO 2602E | E9: 南沙 | F9: 洛杉矶 | G9: 46057 | H9: 46071 | I9: 14 | J9: 46054 | K9: PONTRESINA 2602E 预计开船时间2-11 | L9: 广州华博国际货运有限公司 海关代码4430980A74
A10: 华南-明星达海卡 20T/海派20T | B10: 合德普提 | C10: HDS3 | D10: PORTO 2602E | E10: 南沙 | F10: 洛杉矶 | G10: 46057 | H10: 46071 | I10: 14 | J10: 46054 | K10: PONTRESINA 2602E 预计开船时间2-11 | L10: 广州华博国际货运有限公司 海关代码4430980A74
A11: 华南-OA普船卡派/海派 | B11: 中远 | C11: SEA | D11: COSCO SHIPPING DENALI 051E | E11: 盐田 | F11: 长滩 | G11: 46058 | H11: 46075 | I11: 15 | J11: 46054 | K11: COSCO SPAIN 077E 预计开船时间 2-12 | L11: 深圳市一路通达报关服务有限公司 海关代码4403980A0V
B12: 中远 | C12: SEA3 | D12: OOCL ROTTERDAM 161E | E12: 盐田 | F12: 长滩 | G12: 46063 | H12: 46077 | I12: 14 | J12: 46059 | K12: OOCL UTAH 082E 预计开船时间 2-17 | L12: 深圳市一路通达报关服务有限公司 海关代码4403980A0V
B13: 长荣 | C13: HTW | D13: EVER MAGUS 1439-005E | E13: 盐田 | F13: 洛杉矶 | G13: 46062 | H13: 46076 | I13: 13 | J13: 46059 | K13: EVER MAGNA 1440-003E 预计开船时间 2-17 | L13: 深圳市一路通达报关服务有限公司 海关代码4403980A0V
A14: 华南-特惠线普船卡派 | B14: WHL | C14: AP1 | D14: WAN HAI A05 E014 | E14: 蛇口 | F14: 洛杉矶 | G14: 46064 | H14: 45715 | I14: 18 | J14: 46059 | K14: HYUNDAI NEPTUNE 042E 预计开船时间 2-19 | L14: 深圳市一路通达报关服务有限公司 海关代码4403980A0V
A15: 华南-西雅图普船卡派 暂停本渠道 | B15: YML | C15: PN1 | D15: / | E15: 宁波 | F15: 塔科马 | G15: / | H15: / | I15: / | J15: / | K15: / | L15: /
A16: 华南-奥克兰普船卡派 | B16: 长荣 | C16: HTW | D16: EVER MAGUS 1439-005E | E16: 盐田 | F16: 洛杉矶 | G16: 46062 | H16: 46081 | I16: 20 | J16: 46059 | K16: EVER MAGNA 1440-003E 预计开船时间 2-17 | L16: 深圳市一路通达报关服务有限公司 海关代码4403980A0V
A17: 华南-芝加哥普船卡派 （OA/EXX/ZIM/SML统配） | B17: 达飞 | C17: EXX | D17: CMA CGM TARPON 0GVLUE1MA | E17: 上海 | F17: 芝加哥 | G17: 46058 | H17: 46079 | I17: 21 | J17: 46054 | K17: CMA CGM SWORDFISH 0GVLWE1MA 预计开船时间 2-12 | L17: 义乌市乐通报关代理有限公司 海关代码331898008Q
B18: 长荣 | C18: HTW | D18: EVER MAGUS 1439-005E | E18: 盐田 | F18: 洛杉矶 | G18: 46062 | H18: 3月3 | I18: 24 | J18: 46059 | K18: EVER MAGNA 1440-003E 预计开船时间 2-17 | L18: 深圳市一路通达报关服务有限公司 海关代码4403980A0V
B19: 以星 | C19: ZX2 | D19: PELICAN I 10E | E19: 宁波 | F19: 芝加哥 | G19: 46058 | H19: 46076 | I19: 18 | J19: 46054 | K19: GANGES 16E 预计开船时间 2-12 | L19: 义乌市乐通报关代理有限公司 海关代码331898008Q
A20: 华南-休斯顿普船卡派 | B20: COSCO | C20: GME | D20: XIN DA YANG ZHOU 106E | E20: 盐田 | F20: 休斯顿 | G20: 46063 | H20: 46087 | I20: 26 | J20: 46058 | K20: XIN YA ZHOU174E 预计开船时间 2-16 | L20: 深圳市一路通达报关服务有限公司 海关代码4403980A0V
A21: 华南-萨凡纳普船卡派 | B21: COSCO | C21: AWE3 | D21: EVER MAST 1344-009E | E21: 盐田 | F21: 萨凡纳 | G21: 46062 | H21: 46093 | I21: 31 | J21: 46058 | K21: EVER MACRO 1345-007E 预计开船时间 2-16 | L21: 深圳市一路通达报关服务有限公司 海关代码4403980A0V
A22: 华南-纽约经济普船卡派 | B22: ZIM | C22: ZXB | D22: ZIM SCORPIO 8E | E22: 盐田 | F22: 纽约 | G22: 46060 | H22: 46092 | I22: 32 | J22: 46056 | K22: ZIM CORAL 10E 预计开船时间 2-11 | L22: 深圳市一路通达报关服务有限公司 海关代码4403980A0V
A23: 华南-纽约普船卡派 | B23: COSCO | C23: AWE4 | D23: 072E OOCL Egypt | E23: 盐田 | F23: 纽约 | G23: 46061 | H23: 46091 | I23: 30 | J23: 46057 | K23: OOCL LILAC 003E 预计开船时间 2-15 | L23: 深圳市一路通达报关服务有限公司 海关代码4403980A0V
A24: 报关行——深圳市一路通达报关服务有限公司 海关代码4403980A0V 出境关别 ：5316（大鹏海关） 离境口岸：470601（盐田）
A25: 报关行——深圳市一路通达报关服务有限公司 海关代码4403980A0V 出境关别 ：5304（蛇口海关） 离境口岸：选择SCT（蛇口）
A26: 报关行——广州华博国际货运有限公司 海关代码4430980A74 出境关别 ：5166（南沙新港） 离境口岸：443404一期/443405二期/443417三期
A27: 报关行——义乌市乐通报关代理有限公司 海关代码331898008Q 出境关别：2225（上海），离境口岸：外高桥（310701） 离境口岸：宁波北仑港港区（380101） 出境关别：3104（北仑）
A28: 报关行——易豹网络科技有限公司 海关代码3302480076 出境关别：2225（上海）离境口岸：外高桥（310701） 离境口岸：宁波北仑港港区（380101） 出境关别：3104（北仑）

Sheet MXD-赔偿说明及发货须知
B4: 赔偿标准和免赔声明 | N4: =目录!H4 -> 明日之星华南价格表入仓执行日期2025/1/27
B6: 一、时效赔付界定：以不同渠道时效说明为准 | J6: 美国专线发货须知
B8: 二、时效免赔说明 | J8: 发 货 须 知
B10: 1、船公司船期/航线变更/延迟到港，自然灾害、天气原因，如台风、地震、洪水、冰雹,，暴风雪，雾；政府行为，社会异常事件包括战争，罢工等； | J10: 1、以上价格为普货产品到最终Amazon仓库的全部价格。
B11: 2、海关查验； | J11: 2、FBA货物每件货物需贴2个以上合格的FBA标签,货物尺寸
B12: 3、亚马逊拒收或者亚马逊更改预约时间； | J12: 3、此价格只收普货。带电产品只接内置纽扣电池 仿牌，液体，粉末，美国对华反倾销产品等敏感货物不接。不接收食品类，医疗类产品类，汽车灯、化妆品类（含纹身美妆产品），电子烟及烟草相关产品，动物皮毛制品类，激光产品类，成人用品类，管制刀具和警棍、电棒类，植物种子类，强磁类（磁铁、冰箱贴等），灭蚊、捕鼠、杀虫类产品，杂志书籍出版物，如发现冲货或者带电不备注行为没收货物并罚款RMB1000-RMB50000元：不接收原木
B13: 4、亚马逊爆仓及预约困难； | J13: 4、海关要求如实申报，否则造成延误和丢失以及扣关我司一概不负责
B14: 5、客户FBA ID & 内部编码失误等相关原因； | J14: 5、订舱需提供出货模块资料，模块资料需提供详细品名，海关编码，材质，用途
B15: 6、客户要求扣货后派送或者因客户自身原因导致的延误； | J15: 6、因客户，亚马逊，UPS等海外服务商原因产生海外退件，退件运费及相关退件费用将无条件由发件人支付
B16: 7、由于疫情，国内仓库无法出货，船公司卸船效率慢，预约困难，拒收等不可抗力导致的延迟交仓,不在赔偿范围,此项如与具体渠道的时效赔付标准有区分，则与具体渠道的标准为准； | J16: 7、资料要求：按要求提供货物的真实信息，提供准确的美国的海关编码，如不能提供准确的美国的海关编码,我司清关行会根据实际品名,材质和用途申报，最终产生的关税以海关提供的税金单为准，不得争议。实际货物必须如实申报，货物信息要与发票资料一致，不可瞒报漏报（例如：有牌子申报无牌）和申报不符，如因申报不符导致海关扣货等后果及产生的所有费用由发货人承担
J17: 8、儿童用品出货标准： 1.儿童用品，限时达渠道不接，其他渠道必须提供cpc、cpsc、英文标签。 2.如遇海关查验，产品与认证问题导致后果，以海关查验处理为最终依据，如产生罚款，客人承担。 3.如因产品或认证问题，导致的产品罚没，我司不承担任何责任；如被海关销毁，销毁费用及罚款由客人承担；罚没或销毁无赔偿。 (注：目前国内外海关对于儿童用品进行布控，查验率增加，一旦被海关查验，查验的周期会非常久，望慎重）
B18: 三、赔偿标准（所有赔偿只有一种，不能多种赔偿同时赔付）
B20: 1、在运输过程中如是我司原因导致货物丢失，损坏,经我司确认后按货物申报货值赔偿，最高不超40RMB/KG赔偿，不免相关物流费用。理赔需要提供采购发票等相关资料，以便对货值的合理性进行评估。即40RMB/KG，采购货值，申报货值三者取低赔偿 ；
B21: 2、高货值产品及易碎品建议客人购买保险并打好包装，我司亦可提供购买保险服务；如若在运输过程中出因现包装原因而造成的损失而客人没有购买保险，我司概不负责； | J21: 9、根据现场查验情况，海关针对电池产品(充电宝，锂电池组，储能电源，工具电池，蓄电池等纯电产品)以及电动车类产品(电动滑板车，电动自行车，平衡车等)开展专项指令查验，如遇. 上述产品查验布控指令带“核验是否含有电池等维修货物”、“核验危险品”、“取样送检”等指令,查验需要核查产品上的标签标识是否合格、运输包装是否合格,核验是否有相关检测证书，是否提前规范申报危险品货物信息;并且会有.上报海事部门的风险，还可能会暂扣相关货物送检。由此可能会影响到整个柜子的放行时间，请大家合理安排此类产品的出货计划，避免不必要的损失。凡遇到相关布控指令，我司不承担相关查验费用。（*带电池产品，提供MSDS+货物鉴定书给报关行，报关行给船公司审核，审核通过后可以出）
B22: 3、卡派货交亚马逊仓库，POD（预约号与FBA ID无法对应），但是整票未上架的，我司接受理赔申请，赔偿金额按照我司合同条款 ；（不包括FBA号过期导致的亚马逊拒收和不上架 ；FBA号过期后客户仍然要求我们派送，导致的亚马逊拒收和不上架） | J22: 10、如美国海关认定货物涉及品牌侵权或蓝牙、HDMI、FCC、UL、FDA,DOT，EPA等认证问题，客户需按要求提供相关认证和品牌授权书等文件，如因无法提供或者提供的文件得不到美国海关及相关部门的认可而导致扣货或者退运，所有责任和费用由该发货人承担
B23: 4、快递货交私人仓库/商业地址/亚马逊仓库，如若是整票未提取，我司接受理赔申请，赔偿金额按照我司合同条款（不包括FBA号过期导致的亚马逊拒收和不上架 ；FBA号过期后客户仍然要求我们派送，导致的亚马逊拒收和不上架）； | J23: 11、此上包含海关查验及查验引起的费用（含查验费指普通进口美国查验产生的费用，查验结果最后海关放行且不产生扣货/退运等结果的普通查验费。若查验原因是因为客户的产品及相关证明文件引起的海关查验、扣货、退运等结果产生的所有相关费用由发货方承担)及亚马逊爆仓引起的仓租/柜租以及亚马逊拒收产生的相关费用； 不可抗力因素造成的时效延误不在赔偿范围内，如（包括但不限于）：自然灾害、如台风、地震、洪水、冰雹,，暴风雪；政府行为，社会异常事件，如罢工、码头停摆，骚乱三方面，疫情原因等。如因报关资料问题引起的出口查验由客户承担所有相关费用（如仓租，柜租，改船费等）
B24: 5、快递货交私人仓库/商业地址/亚马逊仓库，快递显示部分未提取+部分已经签收，收货人反馈未收到货物或收到部分货物，我司能够接受理赔，但是私人仓库和商业地址需要签收人提供相应的情况说明书签字（需要显示个人Passport No.）； | J24: 12、以下情况，我司会协助处理，不承担任何责任 A.产品如需要FCC,CE,FDA,TSCA,DOT，CPSC,CPC，EPA等认证而客户无法提供有效证明及文件，导致海关扣货等后果 B.产品不符合美国当地法规的，如反倾销，侵权且无法提供有效证及及文件，导致海关扣货等后果 如因以上情况而产生的退运，销毁，仓租等一切费用，由发货方自行承担
B25: 6、卡派货交亚马逊仓库，POD（预约号与FBA ID无法对应），但是部分上架或部分不上架，未上架部分我司根据具体情况给出处理方案。如若确认理赔，赔偿金额按照我司合同条款标准（不包括FBA号过期导致的亚马逊拒收和不上架 ；FBA号过期后客户仍然要求我们派送，导致的亚马逊拒收和不上架）；丢件赔偿标准如下： 一.快递派标准 （1） 提取前任何形式的丢件 按货值赔偿（提供货值证明）最高不超过40/kg 不退运费 （2）提取上网后丢件 统一按照每件100美金赔偿 不退运费 二.卡派标准 （包含任何形式的丢件） （1）按公斤计费的丢件 按货值赔偿（提供货值证明）最高不超过40RMB/kg 不退运费 （2）按方计费的丢件 按货值赔偿（提供货值证明）最高不超过600RMB/件 不退运费 | J25: 13、请留意，按照美国海关要求，所有中国出口美国货物的外包装及货物内包装（或者货物本身）必须有MADE IN CHINA的标记，否则一旦被查到将会被要求在美国海关的监管下逐件贴标，限期未完成者将会被处以至少为发票金额的6倍的罚款，由此导致的时效延误及一切费用概由客户承担
J26: 14、P.O.BOX军方地址不接（以上价格不含阿拉斯加，夏威夷，波多黎各，关岛及各岛屿，以上城市来电询价）
J27: 15、如亚马逊拒收货件，私人地址拒收货物，产生的退回运费以及其他任何额外费用，客户自理,因客户产品问题导致海关扣关，我司会负责协助清关处理，但不承担任何责任
J28: 16、因美国本地费用变化频繁且即时生效，我司保留即时更改价格的权利（包括在途中的货物）
J29: 特别提示：如客户一旦交货到我司，我司默认为客户已详细阅读过此价格表备注内容及其说明，并接受其条款的约束。 最终解释权归本司所有
B31: 四、免赔声明 | J31: 拒接违禁品
B33: 1、 货物本身侵权问题，货物没按实际价值申报问题、当地禁止进口问题，货物本身质量问题以及涉及到具体的认证问题等导致的海关查验、扣货、退运等情况; | J33: 1、易爆物品：如烟火制品（礼花、鞭炮、摔炮、拉炮等）发令纸、干冰、打火机、煤气炉、煤气罐、火柴、火药，点火器等
B34: 2、如遇自然灾害（火灾、水灾、地震等）或当地罢工等不可抗因素导致货物丢失的； | J34: 2、气体、粉末状物品（有刺激异味伤害皮肤的化工粉末）、膏状物品（如锡膏等）、白色晶状物品
B35: 3、外包装无损情况下，内包装产品数量缺少、部份丢失/损坏； | J35: 3、液体(不论是否易燃)：如汽油、煤油、柴油、苯、酒精、油漆、涂料、油墨、去光液等化学液体
B36: 4、尾端快递派免赔说明： *货交私人仓库/商业地址，快递已经全部显示签收，但是反馈并未收到货物/ 部分未签收； *货交私人仓库/商业地址，快递显示部分递送中+部分已经签收，收货人反馈未收到货物或收到部分货物 *货交私人仓库/商业地址，签收后以签收单上面标注的为准（例如标注了少货或货损），我司协助推进快递服务商开查，不承担其它责任。 *货交亚马逊仓库，快递已经全部显示签收，但是客户亚马逊后台未上架 **货交亚马逊仓库，快递显示部分递送中+部分已经签收，客户反馈亚马逊后台未上架 （递送中迟迟未更新状态） | J36: 4、易燃固体、自燃物品和遇湿易燃物品：如煤、松香、石蜡、活性碳、白磷、黄磷、油麻、金属钠、镁铝粉、锂电、蓄电池等
J37: 5、化学品：如氧化氢、过氧化钠、次氯酸钙、氯酸钾、硝酸钾、不明化学物品等
J38: 6、毒害品和感染性物品。指在流通过程中容易发生中毒和感染的物品 ，如杀虫剂、灭草剂、砷及其化合物、汞及其化合物、氰及其化合物、哥罗芳、苯铵、生漆、血液、尿液、体液、炭疽、危险性病菌等
J39: 7、腐蚀品，能灼烧人体组织，并对金属等物品造成损坏的固体和液体 ，如硫酸、硝酸、 盐酸、氯磺酸、冰醋酸、烧碱、双氧 等
B40: 5. 尾端卡派免赔说明： *私人仓库/商业地址，卡派POD已经显示签收，但是反馈并未收到货物/ 部分未签收； *私人仓库/商业地址，签收后签收单上面未注明有少货或货损 *货送亚马逊，有签名的POD，同一票货，部分货物已经上架不再接受理赔. | J40: 8、化妆品、护肤品、洗漱用品，食品，药品（如牙膏、洗面乳、 护手霜、沫浴露、洗发水等）
J41: 9、各种货币；
B42: 6、申请UPS/FEDEX索赔期限及规则：追诉期从打单之日起算100个自然日内，且快递轨迹停更之日起算45个自然日内，同时满足两个条件可发起开查申请，逾期将不予以受理开查申请，产生的相应责任及损失由客户自行承担。船期超过50天以上的，将在目的港更换UPS面单。 ①未提取的 ，快递官方不受理索赔申请，请按“五、申请索赔期限及规则”中第2条标准处理；②若提取后迟迟未有动态，请在快递轨迹停更后7个工作日向我司客服人员发起开查申请，同时提供快递开查相关资料，最晚发起时间应当在快递轨迹停更之日(含停更当天)起45个自然日内提供完整资料，逾期我司将不再接受理赔申请。 申请索赔需要提供如下资料：①已提取未有动态的：开查的UPS/FEDEX模板+INV+未上架截图(需带有电脑屏幕右下角当下真实时间)；②未提取的：未提取开查表+未上架截图(需带有电脑屏幕右下角当下真实时间) （索赔资料可能会有变动，具体以我司/快递公司要求为准） 注：若逾期未提供完整相应索赔资料导致超期申请索赔，则相应责任由客户自行承担，我司不再接受理赔申请。 | J42: 10、容易腐烂的物品
J43: 11、仿牌商品
J44: 12、医疗用品
J45: 13、各类食品
B46: 7、漏报关赔偿：按3倍报关费赔偿，则3*350元 | J46: 14、各类放射性元素及容器
B47: 8、如出现未上架情况，请按要求提供相关资料进行索赔，如未上架截图，形式发票/装箱单/采购发票等 | J47: 15、各类武器、弹药或者盛装的容器，
J48: 16、管制器具：任何刀刃超过9CM的刀具，或者具备人身攻击的用品
B49: 五、申请索赔期限及规则： | J49: 17、贵金属或者高价值无牌
...

Sheet 明日之星下单渠道明细归类
H3: =目录!H4 -> 明日之星华南价格表入仓执行日期2025/1/27
B4: 浙江明日之星供应链管理有限公司(深圳分公司）
B6: 明日之星下单渠道明细归类
B8: 序号 | C8: 下单渠道名 | D8: 船司 | E8: 参考时效：开船后 | G8: 序号 | H8: 下单渠道名 | I8: 船司 | J8: 参考时效：开船后
B9: 1 | C9: MXD-华南明星达海派14T | D9: MATSON-CLX | E9: 11-14天提取 | G9: 28 | H9: MXD-华南普船特惠线海派 | I9: SML/CUL/OA | J9: 25-28天入仓
B10: 2 | C10: MXD-华南明星达卡派14T | D10: MATSON-CLX | E10: 13-15天入仓 | G10: 29 | H10: MXD-华南普船特惠线卡派按方包税 | I10: SML/CUL/OA | J10: 25-28天入仓
B11: 3 | C11: MXD-华南明星达14T私人卡派 | D11: MATSON-CLX | E11: 提柜之后3-5天 | G11: 30 | H11: MXD-华南普船特惠线留仓自提 | I11: SML/CUL/OA | J11: 提柜之后3-5天
B12: 4 | C12: MXD-华南明星达14T留仓自提 | D12: MATSON-CLX | E12: 提柜之后3-5天 | G12: 31 | H12: MXD-华南普船特惠线私人卡派 | I12: SML/CUL/OA | J12: 提柜之后3-5天
B13: 5 | C13: MXD-华南明星达14T按方卡派 | D13: MATSON-CLX | E13: 13-15天入仓 | G13: 32 | H13: MXD-华南西雅图普船私卡 | I13: SML | J13: 提柜之后5-7天
B14: 6 | C14: MXD-华南明星达海派16T | D14: MATSON-MAX | E14: 12-15天提取 | G14: 33 | H14: MXD-华南西雅图普船卡派 | I14: SML | J14: 35-40天入仓
B15: 7 | C15: MXD-华南明星达卡派16T | D15: MATSON-MAX | E15: 14-16天入仓 | G15: 34 | H15: MXD-华南西雅图普船按方包税 | I15: SML | J15: 35-40天入仓
B16: 8 | C16: MXD-华南明星达16T私人卡派 | D16: MATSON-MAX | E16: 提柜之后3-5天 | G16: 35 | H16: MXD-华南西雅图普船留仓自提 | I16: SML | J16: 提柜之后5-7天
B17: 9 | C17: MXD-华南明星达16T留仓自提 | D17: MATSON-MAX | E17: 提柜之后3-5天 | G17: 36 | H17: MXD-华南奥克兰普船私卡 | I17: CMA/EMC | J17: 提柜之后5-7天
B18: 10 | C18: MXD-华南明星达16T按方卡派 | D18: MATSON-MAX | E18: 12-15天提取 | G18: 37 | H18: MXD-华南奥克兰普船卡派 | I18: CMA/EMC | J18: 25-30天入仓
B19: 11 | C19: MXD-华南明星达海派18T | D19: CMA/ZIM | E19: 13-16天提取 | G19: 38 | H19: MXD-华南奥克兰普船按方包税 | I19: CMA/EMC | J19: 25-30天入仓
B20: 12 | C20: MXD-华南明星达卡派18T | D20: CMA/ZIM | E20: 15-18天入仓 | G20: 39 | H20: MXD-华南奥克兰普船留仓自提 | I20: CMA/EMC | J20: 提柜之后5-7天
... B35: 27 | C35: MXD-华南普船特惠线直送卡派 | D35: SML/CUL/OA | E35: 26-33天入仓 | G35: 54 | H35: MXD-华南纽约普船按方包税 | I35: COSCO | J35: 40-45天入仓
G36: 55 | H36: MXD-华南纽约普船留仓自提 | I36: COSCO | J36: 提柜之后5-7天
G37: 53 | H37: MXD-华南经济纽约普船卡派 | I37: ZIM | J37: 42-48天入仓
G38: 54 | H38: MXD-华南经济纽约普船按方包税 | I38: ZIM | J38: 42-48天入仓
G39: 55 | H39: MXD-华南经济纽约普船留仓自提 | I39: ZIM | J39: 提柜之后5-7天

Sheet MXD-华南海派全渠道
F2: =目录!H4 -> 明日之星华南价格表入仓执行日期2025/1/27
B4: 浙江明日之星供应链管理有限公司(深圳公司）
B6: 华南OA普船海派 （盐田 精品COSCO SEA/SEA3航线)
B7: 100KG+泡重比优惠：1:140减0.5、1:110减1、1:80减1.5
B8: 100KG+实重比优惠：1:190减0.5、1:290减1、1:390减1.5、1:500及以上减2
B9: 国家 | C9: 东莞仓(明星仓5号）福永仓（明星仓6号） | F9: 备注
C10: 12KG+ | D10: 51KG+ | E10: 100KG+
B11: 美东（USE） 邮编0,1,2,3 | C11: 14.9 | D11: 10.9 | E11: 9.9 | F11: 参考时效：开船后25-28天提取 联邦和UPS随机打单 | G11: 报关费：150/票 不同渠道不能合并报关 | H11: 非亚马逊地址+1 偏远3/KG 超偏远4/KG 超极偏远5/KG，如需指定打单+5
B12: 美中（USM） 邮编4,5,6,7 | C12: 14.4 | D12: 10.4 | E12: 9.4
B13: 美西（USW） 邮编8,9 | C13: 12.4 | D13: 8.4 | E13: 7.4
B15: 华南明星达20T海派（精品HDS3航线）
B16: 100KG+泡重比优惠：1:140减0.5、1:110减1、1:80减1.5
B17: 100KG+实重比优惠：1:190减0.5、1:290减1、1:390减1.5、1:500及以上减2
B18: 国家 | C18: 东莞仓(明星仓5号）福永仓（明星仓6号） | F18: 备注
C19: 12KG+ | D19: 51KG+ | E19: 100KG+
B20: 美东（USE） 邮编0,1,2,3 | C20: 15.9 | D20: 11.9 | E20: 10.9 | F20: 1、如遇海关查验，在承诺时效内，不做赔偿;超出承诺时效，退0.5元/KG。其他不可抗力因素无赔偿(如船坏，码头罢工，UPS/FEDEX爆仓等） 2、时效承诺:开船后第二天开始算，21天提取(如遇船舶晚开，晚到港，节假日顺延) 。超21天每天赔付0.5元/kg，最高赔付3元，当天提取不计赔付 | G20: 报关费：150/票 不同渠道不能合并报关 | H20: 非亚马逊地址+1 偏远3/KG 超偏远4/KG 超极偏远5/KG，如需指定打单+5
B21: 美中（USM） 邮编4,5,6,7 | C21: 15.4 | D21: 11.4 | E21: 10.4
B22: 美西（USW） 邮编8,9 | C22: 13.4 | D22: 9.4 | E22: 8.4
B26: 华南明星达18T海派（精品EXX/HDS3快提/ZEX快船航线）
B27: 100KG+泡重比优惠：1:140减0.5、1:110减1、1:80减1.5
B28: 100KG+实重比优惠：1:190减0.5、1:290减1、1:390减1.5、1:500及以上减2
B29: 国家 | C29: 东莞仓(明星仓5号）福永仓（明星仓6号） | F29: 备注
C30: 12KG+ | D30: 51KG+ | E30: 100KG+
B31: 美东（USE） 邮编0,1,2,3 | C31: 16.9 | D31: 12.9 | E31: 11.9 | F31: 1、如遇海关查验，在承诺时效内，不做赔偿;超出承诺时效，退0.5元/KG。其他不可抗力因素无赔偿(如船坏，码头罢工，UPS/FEDEX爆仓等） 2、时效承诺:开船后第二天开始算，19天提取(如遇船舶晚开，晚到港，节假日顺延) 。超19天每天赔付0.5元/kg，最高赔付3元，当天提取不计赔付 | G31: 报关费：150/票 不同渠道不能合并报关 | H31: 非亚马逊地址+1 偏远3/KG 超偏远4/KG 超极偏远5/KG，如需指定打单+5
B32: 美中（USM） 邮编4,5,6,7 | C32: 16.4 | D32: 12.4 | E32: 11.4
B33: 美西（USW） 邮编8,9 | C33: 14.4 | D33: 10.4 | E33: 9.4
B35: 华南明星达16T海派 (美森MAX航线）
B36: 100KG+泡重比优惠：1:140减0.5、1:110减1、1:80减1.5
B37: 100KG+实重比优惠：1:190减0.5、1:290减1、1:390减1.5、1:500及以上减2
B38: 国家 | C38: 东莞仓(明星仓5号）福永仓（明星仓6号） | F38: 备注
C39: 12KG+ | D39: 51KG+ | E39: 100KG+
B40: 美东（USE） 邮编0,1,2,3 | C40: 18.8 | D40: 14.8 | E40: 13.8 | F40: 1、如遇海关查验，在承诺时效内，不做赔偿;超出承诺时效，退0.5元/KG。其他不可抗力因素无赔偿；(如船坏，码头罢工，UPS/FEDEX爆仓等） 2、时效承诺:开船后第二天开始算，17天提取(如遇船舶晚开，晚到港，节假日顺延) 。超17天每天赔付0.5元/kg，最高赔付3元，当天提取不计赔付 | G40: 报关费：150/票 不同渠道不能合并报关 | H40: 非亚马逊地址+1 偏远3/KG 超偏远4/KG 超极偏远5/KG，如需指定打单+5
B41: 美中（USM） 邮编4,5,6,7 | C41: 18.3 | D41: 14.3 | E41: 13.3
B42: 美西（USW） 邮编8,9 | C42: 16.3 | D42: 12.3 | E42: 11.3
B44: 华南明星达14T海派(美森CLX航线）
B45: 100KG+泡重比优惠：1:140减0.5、1:110减1、1:80减1.5
B46: 100KG+实重比优惠：1:190减0.5、1:290减1、1:390减1.5、1:500及以上减2
B47: 国家 | C47: 东莞仓(明星仓5号）福永仓（明星仓6号） | F47: 备注
C48: 12KG+ | D48: 51KG+ | E48: 100KG+
B49: 美东（USE） 邮编0,1,2,3 | C49: 19.1 | D49: 15.1 | E49: 14.1 | F49: 1、如遇海关查验，在承诺时效内，不做赔偿;超出承诺时效，退0.5元/KG。其他不可抗力因素无赔偿(如船坏，码头罢工，UPS/FEDEX爆仓等） 2、时效承诺:开船后第二天开始算，15天提取(如遇船舶晚开，晚到港，节假日顺延) 。超15天每天赔付0.5元/kg，最高赔付3元，当天提取不计赔付 | G49: 报关费：150/票 不同渠道不能合并报关 | H49: 非亚马逊地址+1 偏远3/KG 超偏远4/KG 超极偏远5/KG，如需指定打单+5
...

Sheet 华南明星达14T卡派
G2: =目录!H4 -> 明日之星华南价格表入仓执行日期2025/1/27
B3: 浙江明日之星供应链管理有限公司(深圳分公司）
B5: 华南明星达14T卡派（美森CLX)
B7: 仓库代码 | C7: 东莞仓(明星仓5号）福永仓（明星仓6号） | F7: 起收重量 | G7: 开船后第二天开始计算 （有赔偿） | H7: 备注
C8: 12KG+ | D8: 50KG+ | E8: 按方包税1CBM+
B9: ONT8/LGB8/LAX9/SBD1 | C9: 9.7 | D9: 8.7 | E9: =D9*200 -> 1740 | F9: 12KG+/1CBM+ | G9: 18天签收入仓 | H9: 此报价只收普货，如发现冲货，瞒报或者带电不备注行为没收货物并罚款1000-50000RMB.
B10: LAS1/GYR3/GYR2/SMF3/ SCK4/VGT2 | C10: 10.2 | D10: 9.2 | E10: =D10*200 -> 1840 | F10: 12KG+/1CBM+ | G10: 19天签收入仓
B11: 开船后第二天开始计算时效，超过承诺时效，按照每天赔偿（退0.5元/KG，80/方），最高理赔（1元/KG，160/cbm）签收当天不计赔偿日。1、如遇船司晚开、晚到、节假日时效顺延。2、如遇海关查验后放行还在承诺时效内，不做赔偿:超出承诺时效,统一退（退0.5元/KG，80/方）不参与时效赔偿承诺。3、码头停摆、罢工、恶劣天气等不可抗拒因素无赔偿，如遇亚马逊删约、跳约等无赔偿。
B13: 华南明星达14T卡派（美森CLX)
B15: 仓库代码 | C15: 东莞仓(明星仓5号）福永仓（明星仓6号） | F15: 起收重量 | G15: 参考时效开船后（无赔偿） | H15: 备注
C16: 12KG+ | D16: 50KG+ | E16: 按方包税1CBM+
B17: POC1/POC3/POC2 | C17: 9.7 | D17: 8.7 | E17: =D17*200 -> 1740 | F17: 12KG+/1CBM+ | G17: 19天左右签收入仓 | H17: 1.拒接一切敏感货物，此报价只收普货，如发现冲货，瞒报或者带电不备注行为在我司仓库查到的没收货物并罚款1万-5万元，若因冲货导致海关查验的罚款20万并追究其法律责任，和一切损失 . 3.按方渠道密度比最高（1CBM：363KGS）M：363KGS）
B18: GEU3/GEU5/GEU2/MIT2/TCY2/TCY1/QXY8/SCK8/MCC1/HLI2 | C18: 9.9 | D18: 8.9 | E18: =D18*200 -> 1780 | F18: 12KG+/1CBM+ | G18: 18-22天左右签收
B19: IUSQ/IUSJ/IUSP/IUSW/IUTI/PSP3 | C19: 9.9 | D19: 8.9 | E19: =D19*200 -> 1780 | F19: 12KG+/1CBM+ | G19: 18-22天左右签收
B20: ABQ2 | C20: 10.9 | D20: 9.9 | E20: =D20*200 -> 1980 | F20: 12KG+/1CBM+ | G20: 18-22天左右签收
B21: PSC2 | C21: 11.7 | D21: 10.7 | E21: =D21*200 -> 2140 | F21: 12KG+/1CBM+ | G21: 18-24天左右签收
B22: FTW1/IAH3/AMA1/DFW6 | C22: 11.8 | D22: 10.8 | E22: =D22*200 -> 2160 | F22: 12KG+/1CBM+ | G22: 18-24天左右签收
B23: FWA4/IND9/MDW2 | C23: 12 | D23: 11 | E23: =D23*200 -> 2200 | F23: 12KG+/1CBM+ | G23: 18-24天左右签收
B24: MEM1/MQJ1/RFD2/SLC2/BNA6 | C24: 12 | D24: 11 | E24: =D24*200 -> 2200 | F24: 12KG+/1CBM+ | G24: 18-24天左右签收
B25: BNA2/DEN8/DEN2 | C25: 12.3 | D25: 11.3 | E25: =D25*200 -> 2260 | F25: 12KG+/1CBM+ | G25: 18-24天左右签收
B26: 仓库代码 | C26: 东莞仓(明星仓5号）福永仓（明星仓6号） | F26: 起收重量 | G26: 参考时效开船后 （无赔偿） | H26: 备注
C27: 12KG+ | D27: 100KG+ | E27: 按方包税1CBM+
B28: ABE8/TEB9/AVP1/CLT2 | C28: 13.7 | D28: 12.7 | E28: =D28*200 -> 2540 | F28: 12KG+/1CBM+ | G28: 20-24天左右签收 | H28: 1.我司拒接一切敏感货物，此报价只收普货，如发现冲货，瞒报或者带电不备注行为在我司仓库查到的没收货物并罚款1万-5万元，若因冲货导致海关查验的罚款20万并追究其法律责任，和一切损失 . 2.不同区不可以合并报关(如：一区不能和二区合并报关) 3.按方渠道密度比最高（1CBM：363KGS）
B29: TEB4/SWF1/SWF2 | C29: 14.3 | D29: 13.3 | E29: =D29*200 -> 2660 | F29: 12KG+/1CBM+ | G29: 22-26天左右签收
B30: ORF2/RMN3/RDU2 | C30: 14.7 | D30: 13.7 | E30: =D30*200 -> 2740 | F30: 12KG+/1CBM+ | G30: 22-26天左右签收
B31: 仓库代码 | C31: 东莞仓(明星仓5号）福永仓（明星仓6号） | F31: 按方包税2CBM+ | H31: 备注
C32: 50KG+ | D32: 100KG+ | E32: 1000KG+
B33: 美西海外仓自提 | C33: 9.4 | D33: 8.7 | E33: 8.7 | F33: =D33*200 -> 1740 | H33: 出库费$15/托，不包含其他费用（如海外仓仓储费，贴标费，派送费等），如有产生实报实销
B34: 90-91商业地址 | C34: 咨询我司客服单独报价 | H34: 不包含其他费用（如海外仓仓储费，贴标费，超时费，二次派送费等额外产生的杂费）如有产生实报实销
B35: 后续关税每上调1%，将对应增加0.03元/kg的费用，按方对应增加6元/方，反之降关税每下调1%，将对应退0.03元/kg的费用，按方对应退6元/方 发货即默认此条款
B36: 50KG+实重比优惠：1:190减0.5、1:250减0.8、1:300减1、1:350减1.3、1:400减1.5、1:450减1.8、1:500及以上减2 比重减后最低1.5/KG
B38: 赔偿说明
B40: 1.提供POD 和预约号后 亚马逊的货物请客户在签收后5个工作日内查询限FBA后台是否上架，签收后15个工作日内提供货物未上架后台截图(需带有电脑屏幕右下角当下真实时间)至我司方可进入开查程序，超过20个工作日反馈不予受理和赔偿。若卡派出现丢件在我司规定时间内调查核实后我司予以赔偿。丢件赔偿标准如下： 一.快递派标准 （1） 提取前任何形式的丢件 按货值赔偿（提供货值证明）最高不超过40/kg 不退运费 （2）提取上网后丢件 统一按照每件100美金赔偿 不退运费 二.卡派标准 （包含任何形式的丢件） （1）按公斤计费的丢件 按货值赔偿（提供货值证明）最高不超过40RMB/kg 不退运费 （2）按方计费的丢件 按货值赔偿（提供货值证明）最高不超过600RMB/件 不退运费 2.货物如因自身包装问题造成破损或数量短少的，不作赔偿； 3.货物未如实申报、侵权或不符合当地法规禁止进口的导致海关扣货不作赔偿, 并且保留追究发件人因此带来对我司的损失赔偿责任； 4.因船期延误或清关延误等不可抗因素，不作赔偿； 5.易碎品不接受任何损坏赔偿； 6.如客户一旦交货到我司，则默认上述赔款条例，出货前请详细阅读此赔偿标准。
B42: 注意事项
B44: 1.以上价格为华南仓库交货价,材积货算:长*宽*高CM/6000 ；
B45: 3.以上价格为普货产品到最终Amazon仓库的全部价格；
B46: 4.可接单独报关件，加收150RMB/票，退税件贸易国只接中国和美国，其他国家或者中国香港无服务；
B47: 5.单票货物超过5个品名，需额外加收30RMB/个；
B48: 6.订舱需提供出货模块资料，模块资料需提供详细品名，海关编码，材质，用途，图片，地址栏需认真仔细填写；
B49: 7.尺寸及重量：实重30-45KG加收1RMB/KG，(150/方）320CM<一长+两宽+两高<410CM加收5RMB/KG（800/方）尺寸及重量规则均叠加收费
...

Sheet 华南明星达16T卡派
G2: =目录!H4 -> 明日之星华南价格表入仓执行日期2025/1/27
B3: 浙江明日之星供应链管理有限公司(深圳分公司）
B5: 华南明星达16T卡派 (美森MAX航线）
B7: 仓库代码 | C7: 东莞仓(明星仓5号）福永仓（明星仓6号） | F7: 起收重量 | G7: 开船后第二天开始计算 （有赔偿） | H7: 备注
C8: 12KG+ | D8: 50KG+ | E8: 按方包税1CBM+
B9: ONT8/LGB8/LAX9/SBD1 | C9: 9.4 | D9: 8.4 | E9: =D9*200 -> 1680 | F9: 12KG+/1CBM+ | G9: 19天签收入仓 | H9: 此报价只收普货，如发现冲货，瞒报或者带电不备注行为没收货物并罚款1000-50000RMB.
B10: LAS1/GYR3/GYR2/SMF3/ SCK4/VGT2 | C10: 9.9 | D10: 8.9 | E10: =D10*200 -> 1780 | F10: 12KG+/1CBM+ | G10: 20天签收入仓
B11: 开船后第二天开始计算时效，超过承诺时效，按照每天赔偿（退0.5元/KG，80/方），最高理赔（1元/KG，160/cbm）签收当天不计赔偿日。1、如遇船司晚开、晚到、节假日时效顺延。2、如遇海关查验后放行还在承诺时效内，不做赔偿:超出承诺时效,统一退（退0.5元/KG，80/方）不参与时效赔偿承诺。3、码头停摆、罢工、恶劣天气等不可抗拒因素无赔偿，如遇亚马逊删约、跳约等无赔偿。
B13: 华南明星达16T卡派 (美森MAX航线）
B15: 仓库代码 | C15: 东莞仓(明星仓5号）福永仓（明星仓6号） | F15: 起收重量 | G15: 参考时效开船后 （无赔偿） | H15: 备注
C16: 12KG+ | D16: 50KG+ | E16: 按方包税1CBM+
B17: POC1/POC3/POC2 | C17: 9.4 | D17: 8.4 | E17: =D17*200 -> 1680 | F17: 12KG+/1CBM+ | G17: 19天左右签收入仓 | H17: 1.我司拒接一切敏感货物，此报价只收普货，如发现冲货，瞒报或者带电不备注行为在我司仓库查到的没收货物并罚款1万-5万元，若因冲货导致海关查验的罚款20万并追究其法律责任，和一切损失 . 3.按方渠道密度比最高（1CBM：363KGS）
B18: GEU3/GEU5/GEU2/MIT2/TCY2/TCY1/QXY8/SCK8/MCC1/HLI2 | C18: 9.6 | D18: 8.6 | E18: =D18*200 -> 1720 | F18: 12KG+/1CBM+ | G18: 18-22天左右签收
B19: IUSQ/IUSJ/IUSP/IUSW/IUTI/PSP3 | C19: 9.6 | D19: 8.6 | E19: =D19*200 -> 1720 | F19: 12KG+/1CBM+ | G19: 18-22天左右签收
B20: ABQ2 | C20: 10.6 | D20: 9.6 | E20: =D20*200 -> 1920 | F20: 12KG+/1CBM+ | G20: 18-22天左右签收
B21: PSC2 | C21: 11.4 | D21: 10.4 | E21: =D21*200 -> 2080 | F21: 12KG+/1CBM+ | G21: 19-25天左右签收
B22: FTW1/IAH3/AMA1/DFW6 | C22: 11.5 | D22: 10.5 | E22: =D22*200 -> 2100 | F22: 12KG+/1CBM+ | G22: 19-25天左右签收
B23: FWA4/IND9/MDW2 | C23: 11.7 | D23: 10.7 | E23: =D23*200 -> 2140 | F23: 12KG+/1CBM+ | G23: 19-25天左右签收
B24: MEM1/MQJ1/RFD2/SLC2/BNA6 | C24: 11.7 | D24: 10.7 | E24: =D24*200 -> 2140 | F24: 12KG+/1CBM+ | G24: 19-25天左右签收
B25: BNA2/DEN8/DEN2 | C25: 12 | D25: 11 | E25: =D25*200 -> 2200 | F25: 12KG+/1CBM+ | G25: 21-27天左右签收
B26: 仓库代码 | C26: 东莞仓(明星仓5号）福永仓（明星仓6号） | F26: 起收重量 | G26: 参考时效开船后 （无赔偿） | H26: 备注
C27: 12KG+ | D27: 100KG+ | E27: 按方包税1CBM+
B28: ABE8/TEB9/AVP1/CLT2 | C28: 13.4 | D28: 12.4 | E28: =D28*200 -> 2480 | F28: 12KG+/1CBM+ | G28: 21-25天左右签收 | H28: 1.我司拒接一切敏感货物，此报价只收普货，如发现冲货，瞒报或者带电不备注行为在我司仓库查到的没收货物并罚款1万-5万元，若因冲货导致海关查验的罚款20万并追究其法律责任，和一切损失 . 2.不同区不可以合并报关(如：一区不能和二区合并报关) 3.按方渠道密度比最高（1CBM：363KGS）
B29: TEB4/SWF1/SWF2 | C29: 14 | D29: 13 | E29: =D29*200 -> 2600 | F29: 12KG+/1CBM+ | G29: 23-27天左右签收
B30: ORF2/RMN3/RDU2 | C30: 14.4 | D30: 13.4 | E30: =D30*200 -> 2680 | F30: 12KG+/1CBM+ | G30: 23-27天左右签收
B31: 仓库代码 | C31: 东莞仓(明星仓5号）福永仓（明星仓6号） | F31: 按方包税1CBM+ | H31: 备注
C32: 50KG+ | D32: 100KG+ | E32: 1000KG+
B33: 美西海外仓自提 | C33: 9.1 | D33: 8.4 | E33: 8.4 | F33: =D33*200 -> 1680 | H33: 出库费$15/托，不包含其他费用（如海外仓仓储费，贴标费，派送费等），如有产生实报实销
B34: 90-91商业地址 | C34: 咨询我司客服单独报价 | H34: 不包含其他费用（如海外仓仓储费，贴标费，超时费，二次派送费等额外产生的杂费）如有产生实报实销
B35: 后续关税每上调1%，将对应增加0.03元/kg的费用，按方对应增加6元/方，反之降关税每下调1%，将对应退0.03元/kg的费用，按方对应退6元/方 发货即默认此条款
B36: 以下仓库10cbm以上可单独咨询我司客服报价
B37: LGB6/SBD2/SNA4/XLX7/SJC7/FAT2/SCK1/ MCE1/PHX5/PHX7/LAS6/OAK3/FOE1/HOU8/ICT2/LIT2/MEM6/MKC4/OKC2/STL3/STL4/CMH2/CMH3/IGQ2/IND5/JVL1/MDW6/ORD2/HIA1 /ILG1/ABE3/MDT1/PHL6/RDU2/RDU4/RYY2/TEB6/ALB1/BWI4/DCA6/MGE3 /PIT2/ RIC1 /RMN3/SAV3/JAX3/PBI3/TMB8/ TPA3/SWF1/SWF2/LAN2/LBE1/TEB9/SLC2
B38: 50KG+实重比优惠：1:190减0.5、1:250减0.8、1:300减1、1:350减1.3、1:400减1.5、1:450减1.8、1:500及以上减2 比重减后最低1.5/KG
B40: 赔偿说明
B42: 1.提供POD 和预约号后 亚马逊的货物请客户在签收后5个工作日内查询限FBA后台是否上架，签收后15个工作日内提供货物未上架后台截图(需带有电脑屏幕右下角当下真实时间)至我司方可进入开查程序，超过20个工作日反馈不予受理和赔偿。若卡派出现丢件在我司规定时间内调查核实后我司予以赔偿。丢件赔偿标准如下： 一.快递派标准 （1） 提取前任何形式的丢件 按货值赔偿（提供货值证明）最高不超过40/kg 不退运费 （2）提取上网后丢件 统一按照每件100美金赔偿 不退运费 二.卡派标准 （包含任何形式的丢件） （1）按公斤计费的丢件 按货值赔偿（提供货值证明）最高不超过40RMB/kg 不退运费 （2）按方计费的丢件 按货值赔偿（提供货值证明）最高不超过600RMB/件 不退运费 2.货物如因自身包装问题造成破损或数量短少的，不作赔偿； 3.货物未如实申报、侵权或不符合当地法规禁止进口的导致海关扣货不作赔偿, 并且保留追究发件人因此带来对我司的损失赔偿责任； 4.因船期延误或清关延误等不可抗因素，不作赔偿； 5.易碎品不接受任何损坏赔偿； 6.如客户一旦交货到我司，则默认上述赔款条例，出货前请详细阅读此赔偿标准。
B44: 注意事项
B45: 1.以上价格为华南仓库交货价,材积货算:长*宽*高CM/6000 。
B46: 3.以上价格为普货产品到最终Amazon仓库的全部价格
B47: 4.可接单独报关件，加收150RMB/票，退税件贸易国只接中国和美国，其他国家或者中国香港无服务。
B48: 5.单票货物超过5个品名，需额外加收30RMB/个。
...

Sheet 华南明星达18T卡派
J3: =目录!H4 -> 明日之星华南价格表入仓执行日期2025/1/27
B4: 浙江明日之星供应链管理有限公司(深圳分公司）
B7: 华南明星达18T卡派
B9: 组合区 | C9: 仓库代码 | D9: 东莞仓(明星仓5号）福永仓（明星仓6号） | G9: 起收重量 | H9: 开船后第二天 开始计算时效签收时效 | I9: 备注
D10: 12KG+ | E10: 50KG+ | F10: 按方包税1CBM+
B11: 一区美西特价 | C11: ONT8/LGB8/LAX9/SBD1 | D11: 5.4 | E11: 4.4 | F11: =E11*200 -> 880 | G11: 12KG+/1CBM+ | H11: 20天签收 | I11: 此报价只收普货，如发现冲货，瞒报或者带电不备注行为没收货物并罚款1000-50000RMB.
B12: 三区美西特价 | C12: GYR2/GYR3/LAS1/SMF3/SCK4/VGT2 | D12: 5.9 | E12: 4.9 | F12: =E12*200 -> 980 | G12: 12KG+/1CBM+ | H12: 21天签收
B13: 开船后第二天开始计算时效，超过承诺时效，按照每天赔偿（退0.5元/KG，80/方），最高理赔（1元/KG，160/cbm）签收当天不计赔偿日。1、如遇船司晚开、晚到、节假日时效顺延。2、如遇海关查验后放行还在承诺时效内，不做赔偿:超出承诺时效,统一退（退0.5元/KG，80/方）不参与时效赔偿承诺。3、码头停摆、罢工、恶劣天气等不可抗拒因素无赔偿，如遇亚马逊删约、跳约等无赔偿。
B15: 华南明星达18T卡派
B17: 组合区 | C17: 仓库代码 | D17: 东莞仓(明星仓5号）福永仓（明星仓6号） | G17: 起收重量 | H17: 参考时效开船后 （无赔偿） | I17: 备注
D18: 12KG+ | E18: 50KG+ | F18: 按方包税1CBM+
B19: 一区美西 | C19: POC1/POC3/ POC2 | D19: 5.6 | E19: 4.6 | F19: =E19*200 -> 920 | G19: 12KG+/1CBM+ | H19: 20天左右签收 | I19: 1.我司拒接一切敏感货物，此报价只收普货，如发现冲货，瞒报或者带电不备注行为在我司仓库查到的没收货物并罚款1万-5万元，若因冲货导致海关查验的罚款20万并追究其法律责任，和一切损失 . 2.不同区不可以合并报关(如：一区不能和二区合并报关) 3.按方渠道密度比最高（1CBM：363KGS）
B20: 二区美西 | C20: LGB4/LGB9/LGB6/SBD2 /SNA4/ XLX7/JOT1 | D20: 5.8 | E20: 4.8 | F20: =E20*200 -> 960 | G20: 12KG+/1CBM+ | H20: 21天左右签收
C21: IUSQ/IUSJ/IUSP/IUTI/IUSW/IUTE/PSP3 | D21: 5.8 | E21: 4.8 | F21: =E21*200 -> 960 | G21: 12KG+/1CBM+ | H21: 21天左右签收
B22: 三区美西 | C22: SCK8/MIT2/HLI2/TCY2/TCY1/MCC1 | D22: 6.3 | E22: 5.3 | F22: =E22*200 -> 1060 | G22: 12KG+/1CBM+ | H22: 19-24天左右签收
C23: GEU3/GEU5/GEU2/QXY5/QXY8 | D23: 6.3 | E23: 5.3 | F23: =E23*200 -> 1060 | G23: 12KG+/1CBM+ | H23: 19-24天左右签收
B24: 四区美西 | C24: SJC7/FAT2/SCK1/ MCE1 | D24: 6.3 | E24: 5.3 | F24: =E24*200 -> 1060 | G24: 12KG+/1CBM+ | H24: 19-24天左右签收
C25: PHX5/PHX7/LAS6/OAK3/SMF6 | D25: 6.3 | E25: 5.3 | F25: =E25*200 -> 1060 | G25: 12KG+/1CBM+ | H25: 19-24天左右签收
C26: ABQ2 | D26: 7.1 | E26: 6.1 | F26: =E26*200 -> 1220 | G26: 12KG+/1CBM+ | H26: 19-24天左右签收
B27: 五区美中 | C27: PSC2 | D27: 7.7 | E27: 6.7 | F27: =E27*200 -> 1340 | G27: 12KG+/1CBM+ | H27: 21-27天左右签收
C28: AMA1/SAT1/SAT4/DFW6/FTW1/IAH3/IUTH/AFW5/FTW5 | D28: 7.9 | E28: 6.9 | F28: =E28*200 -> 1380 | G28: 12KG+/1CBM+ | H28: 21-27天左右签收
C29: FWA4/IND9/MDW2/IUSF | D29: 8.2 | E29: 7.2 | F29: =E29*200 -> 1440 | G29: 12KG+/1CBM+ | H29: 21-27天左右签收
C30: MEM1/MQJ1/RFD2/SLC2/BNA6 | D30: 8.2 | E30: 7.2 | F30: =E30*200 -> 1440 | G30: 12KG+/1CBM+ | H30: 21-27天左右签收
B31: 组合区 | C31: 仓库代码 | D31: 东莞仓(明星仓5号）福永仓（明星仓6号） | G31: 起收重量 | H31: 参考时效开船后 （无赔偿） | I31: 备注
D32: 50KG+ | E32: 100KG+ | F32: 按方包税1CBM+
B33: 六区美中 | C33: BNA2/DEN8/DEN2/FOE1/PPO4 | D33: 8.5 | E33: 7.5 | F33: =E33*200 -> 1500 | G33: 50KG+/1CBM+ | H33: 23-29天左右签收 | I33: 1.我司拒接一切敏感货物，此报价只收普货，如发现冲货，瞒报或者带电不备注行为在我司仓库查到的没收货物并罚款1万-5万元，若因冲货导致海关查验的罚款20万并追究其法律责任，和一切损失 . 2.不同区不可以合并报关(如：一区不能和二区合并报关) 3.按方渠道密度比最高（1CBM：363KGS）
C34: HOU8/ICT2/LIT2/MEM6/MKC4 | D34: 8.5 | E34: 7.5 | F34: =E34*200 -> 1500 | G34: 50KG+/1CBM+ | H34: 23-29天左右签收
C35: OKC2/STL3/STL4/FTW3/BFI3/GEG2 | D35: 8.5 | E35: 7.5 | F35: =E35*200 -> 1500 | G35: 50KG+/1CBM+ | H35: 23-29天左右签收
B36: 七区美中 | C36: CMH2/CMH3/IGQ2/IND2/LAN2 | D36: 8.8 | E36: 7.8 | F36: =E36*200 -> 1560 | G36: 50KG+/1CBM+ | H36: 23-29天左右签收
C37: JVL1/MDW6/ORD2/RFD4/STL6/DET1/DET2 | D37: 8.8 | E37: 7.8 | F37: =E37*200 -> 1560 | G37: 50KG+/1CBM+ | H37: 23-29天左右签收
B38: 组合区 | C38: 仓库代码 | D38: 东莞仓(明星仓5号）福永仓（明星仓6号） | G38: 起收重量 | H38: 参考时效开船后 （无赔偿） | I38: 1.我司拒接一切敏感货物，此报价只收普货，如发现冲货，瞒报或者带电不备注行为在我司仓库查到的没收货物并罚款1万-5万元，若因冲货导致海关查验的罚款20万并追究其法律责任，和一切损失 . 2.不同区不可以合并报关(如：一区不能和二区合并报关) 3.按方渠道密度比最高（1CBM：363KGS）
D39: 12KG+ | E39: 100KG+ | F39: 按方包税1CBM+
B40: 美东纽约专区 | C40: ABE8/AVP1/TEB9/RMN3 | D40: 9.4 | E40: 8.4 | F40: =E40*200 -> 1680 | G40: 12KG+/1CBM+ | H40: 21-27天左右签收
C41: ACY2/TEB3/TEB6/TTN2/ABE4/RDU4/HEA2/RDU2 | D41: 9.9 | E41: 8.9 | F41: =E41*200 -> 1780 | G41: 12KG+/1CBM+ | H41: 25-29天左右签收
C42: TEB4/SWF1/SWF2/MDT1/WBW2 | D42: 9.9 | E42: 8.9 | F42: =E42*200 -> 1780 | G42: 12KG+/1CBM+ | H42: 25-29天左右签收
C43: MDT4/PHL4/PHL5/PHL6/DCA6/ILG1 /IUSL/HIA1 | D43: 10 | E43: 9 | F43: =E43*200 -> 1800 | G43: 12KG+/1CBM+ | H43: 25-29天左右签收
C44: ORF2/RIC1/BOS7/ALB1/XLX1/XRI3 | D44: 10 | E44: 9 | F44: =E44*200 -> 1800 | G44: 12KG+/1CBM+ | H44: 25-29天左右签收
C45: PIT2/LBE1/CHO1/ AKR1 /IUST | D45: 10 | E45: 9 | F45: =E45*200 -> 1800 | G45: 12KG+/1CBM+ | H45: 25-29天左右签收
B46: 组合区 | C46: 仓库代码 | D46: 东莞仓(明星仓5号）福永仓（明星仓6号） | G46: 起收重量 | H46: 参考时效开船后（无赔偿） | I46: 备注
D47: 12KG+ | E47: 100KG+ | F47: 按方包税1CBM+
...

Sheet 华南明星达20T卡派
J4: =目录!H4 -> 明日之星华南价格表入仓执行日期2025/1/27
B5: 浙江明日之星供应链管理有限公司(深圳分公司）
B8: 华南明星达20T卡派(合德HDS3)华南王牌渠道
B10: 组合区 | C10: 仓库代码 | D10: 东莞仓(明星仓5号）福永仓（明星仓6号） | G10: 起收重量 | H10: 开船后第二天 开始计算时效签收时效 | I10: 备注
D11: 12KG+ | E11: 50KG+ | F11: 按方包税1CBM+
B12: 一区美西特价 | C12: ONT8/LGB8/LAX9/SBD1 | D12: 4.6 | E12: 3.6 | F12: =E12*200 -> 720 | G12: 12KG+/1CBM+ | H12: 22天签收 | I12: 此报价只收普货，如发现冲货，瞒报或者带电不备注行为没收货物并罚款1000-50000RMB.
B13: 三区美西特价 | C13: GYR2/GYR3/LAS1/SMF3/SCK4/VGT2 | D13: 5.1 | E13: 4.1 | F13: =E13*200 -> 820 | G13: 12KG+/1CBM+ | H13: 23天签收
B14: 开船后第二天开始计算时效，超过承诺时效，按照每天赔偿（退0.5元/KG，80/方），最高理赔（1元/KG，160/cbm）签收当天不计赔偿日。1、如遇船司晚开、晚到、节假日时效顺延。2、如遇海关查验后放行还在承诺时效内，不做赔偿:超出承诺时效,统一退（退0.5元/KG，80/方）不参与时效赔偿承诺。3、码头停摆、罢工、恶劣天气等不可抗拒因素无赔偿，如遇亚马逊删约、跳约等无赔偿。
B16: 华南明星达20T卡派(合德HDS3)华南王牌渠道
B18: 组合区 | C18: 仓库代码 | D18: 东莞仓(明星仓5号）福永仓（明星仓6号） | G18: 起收重量 | H18: 参考时效开船后 （无赔偿） | I18: 备注
D19: 12KG+ | E19: 50KG+ | F19: 按方包税1CBM+
B20: 一区美西 | C20: POC1/POC3/ POC2 | D20: 4.9 | E20: 3.9 | F20: =E20*200 -> 780 | G20: 12KG+/1CBM+ | H20: 22天左右签收 | I20: 1.我司拒接一切敏感货物，此报价只收普货，如发现冲货，瞒报或者带电不备注行为在我司仓库查到的没收货物并罚款1万-5万元，若因冲货导致海关查验的罚款20万并追究其法律责任，和一切损失 . 2.不同区不可以合并报关(如：一区不能和二区合并报关) 3.按方渠道密度比最高（1CBM：363KGS）
B21: 二区美西 | C21: LGB4/LGB9/LGB6/SBD2 /SNA4/ XLX7/JOT1 | D21: 5.1 | E21: 4.1 | F21: =E21*200 -> 820 | G21: 12KG+/1CBM+ | H21: 23天左右签收
C22: IUSQ/IUSJ/IUSP/IUTI/IUSW/IUTE/PSP3 | D22: 5.1 | E22: 4.1 | F22: =E22*200 -> 820 | G22: 12KG+/1CBM+ | H22: 23天左右签收
B23: 三区美西 | C23: SCK8/MIT2/HLI2/TCY2/TCY1/MCC1 | D23: 5.6 | E23: 4.6 | F23: =E23*200 -> 920 | G23: 12KG+/1CBM+ | H23: 19-24天左右签收
C24: GEU3/GEU5/GEU2/QXY5/QXY8 | D24: 5.6 | E24: 4.6 | F24: =E24*200 -> 920 | G24: 12KG+/1CBM+ | H24: 19-24天左右签收
B25: 四区美西 | C25: SJC7/FAT2/SCK1/ MCE1 | D25: 5.6 | E25: 4.6 | F25: =E25*200 -> 920 | G25: 12KG+/1CBM+ | H25: 19-24天左右签收
C26: PHX5/PHX7/LAS6/OAK3/SMF6 | D26: 5.6 | E26: 4.6 | F26: =E26*200 -> 920 | G26: 12KG+/1CBM+ | H26: 19-24天左右签收
C27: ABQ2 | D27: 6.4 | E27: 5.4 | F27: =E27*200 -> 1080 | G27: 12KG+/1CBM+ | H27: 19-24天左右签收
B28: 五区美中 | C28: PSC2 | D28: 7 | E28: 6 | F28: =E28*200 -> 1200 | G28: 12KG+/1CBM+ | H28: 21-27天左右签收
C29: AMA1/SAT1/SAT4/DFW6/FTW1/IAH3/IUTH/AFW5/FTW5 | D29: 7.2 | E29: 6.2 | F29: =E29*200 -> 1240 | G29: 12KG+/1CBM+ | H29: 21-27天左右签收
C30: FWA4/IND9/MDW2/IUSF | D30: 7.5 | E30: 6.5 | F30: =E30*200 -> 1300 | G30: 12KG+/1CBM+ | H30: 21-27天左右签收
C31: MEM1/MQJ1/RFD2/SLC2/BNA6 | D31: 7.5 | E31: 6.5 | F31: =E31*200 -> 1300 | G31: 12KG+/1CBM+ | H31: 21-27天左右签收
B32: 组合区 | C32: 仓库代码 | D32: 东莞仓(明星仓5号）福永仓（明星仓6号） | G32: 起收重量 | H32: 参考时效开船后 （无赔偿） | I32: 备注
D33: 50KG+ | E33: 100KG+ | F33: 按方包税1CBM+
B34: 六区美中 | C34: BNA2/DEN8/DEN2/FOE1/PPO4 | D34: 7.8 | E34: 6.8 | F34: =E34*200 -> 1360 | G34: 50KG+/1CBM+ | H34: 23-29天左右签收 | I34: 1.我司拒接一切敏感货物，此报价只收普货，如发现冲货，瞒报或者带电不备注行为在我司仓库查到的没收货物并罚款1万-5万元，若因冲货导致海关查验的罚款20万并追究其法律责任，和一切损失 . 2.不同区不可以合并报关(如：一区不能和二区合并报关) 3.按方渠道密度比最高（1CBM：363KGS）
C35: HOU8/ICT2/LIT2/MEM6/MKC4 | D35: 7.8 | E35: 6.8 | F35: =E35*200 -> 1360 | G35: 50KG+/1CBM+ | H35: 23-29天左右签收
C36: OKC2/STL3/STL4/FTW3/BFI3/GEG2 | D36: 7.8 | E36: 6.8 | F36: =E36*200 -> 1360 | G36: 50KG+/1CBM+ | H36: 23-29天左右签收
B37: 七区美中 | C37: CMH2/CMH3/IGQ2/IND2/LAN2 | D37: 8.1 | E37: 7.1 | F37: =E37*200 -> 1420 | G37: 50KG+/1CBM+ | H37: 23-29天左右签收
C38: JVL1/MDW6/ORD2/RFD4/STL6/DET1/DET2 | D38: 8.1 | E38: 7.1 | F38: =E38*200 -> 1420 | G38: 50KG+/1CBM+ | H38: 23-29天左右签收
B39: 组合区 | C39: 仓库代码 | D39: 东莞仓(明星仓5号）福永仓（明星仓6号） | G39: 起收重量 | H39: 参考时效开船后 （无赔偿） | I39: 1.我司拒接一切敏感货物，此报价只收普货，如发现冲货，瞒报或者带电不备注行为在我司仓库查到的没收货物并罚款1万-5万元，若因冲货导致海关查验的罚款20万并追究其法律责任，和一切损失 . 2.不同区不可以合并报关(如：一区不能和二区合并报关) 3.按方渠道密度比最高（1CBM：363KGS）
D40: 12KG+ | E40: 100KG+ | F40: 按方包税1CBM+
B41: 美东纽约专区 | C41: ABE8/AVP1/TEB9/RMN3 | D41: 8.7 | E41: 7.7 | F41: =E41*200 -> 1540 | G41: 12KG+/1CBM+ | H41: 21-27天左右签收
C42: ACY2/TEB3/TEB6/TTN2/ABE4/RDU4/HEA2/RDU2 | D42: 9.2 | E42: 8.2 | F42: =E42*200 -> 1640 | G42: 12KG+/1CBM+ | H42: 25-29天左右签收
C43: TEB4/SWF1/SWF2/MDT1/WBW2 | D43: 9.2 | E43: 8.2 | F43: =E43*200 -> 1640 | G43: 12KG+/1CBM+ | H43: 25-29天左右签收
C44: MDT4/PHL4/PHL5/PHL6/DCA6/ILG1 /IUSL/HIA1 | D44: 9.3 | E44: 8.3 | F44: =E44*200 -> 1660 | G44: 12KG+/1CBM+ | H44: 25-29天左右签收
C45: ORF2/RIC1/BOS7/ALB1/XLX1/XRI3 | D45: 9.3 | E45: 8.3 | F45: =E45*200 -> 1660 | G45: 12KG+/1CBM+ | H45: 25-29天左右签收
C46: PIT2/LBE1/CHO1/ AKR1 /IUST | D46: 9.3 | E46: 8.3 | F46: =E46*200 -> 1660 | G46: 12KG+/1CBM+ | H46: 25-29天左右签收
B47: 组合区 | C47: 仓库代码 | D47: 东莞仓(明星仓5号）福永仓（明星仓6号） | G47: 起收重量 | H47: 参考时效开船后（无赔偿） | I47: 备注
D48: 12KG+ | E48: 100KG+ | F48: 按方包税1CBM+
...

Sheet 华南OA普船卡派
J3: =目录!H4 -> 明日之星华南价格表入仓执行日期2025/1/27
B4: 浙江明日之星供应链管理有限公司(深圳分公司）
B7: 华南OA卡派直送（盐田 COSCO SEA航线)(本周船期OA必保舱位，如因船司爆仓甩柜赔付0.5/KG)
B9: 组合区 | C9: 仓库代码 | D9: 东莞仓(明星仓5号）福永仓（明星仓6号） | G9: 起收重量 | H9: 开船后第二天 开始计算时效签收时效 | I9: 备注
D10: 12KG+ | E10: 50KG+ | F10: 按方包税1CBM+
B11: 洛杉矶特价 | C11: ONT8/LGB8/LAX9/SBD1 | D11: 4.1 | E11: 3.1 | F11: =E11*200 -> 620 | G11: 12KG+/1CBM+ | H11: 19-26天签收 | I11: 此渠道报价为直送柜不接受拦截，若需要拦截每票2200美金/票，不接受合并报关。单件尺寸不超63cm，在截单前到货的保证装走，不集货，不延船期!
C12: GYR2/GYR3/LAS1/SMF3/SCK4/VGT2 | D12: 4.6 | E12: 3.6 | F12: =E12*200 -> 720 | G12: 12KG+/1CBM+ | H12: 19-26天签收
B14: 华南OA拆柜卡派（盐田 COSCO SEA航线)(本周船期OA必保舱位，如因船司爆仓甩柜赔付0.5/KG)
B16: 组合区 | C16: 仓库代码 | D16: 东莞仓(明星仓5号）福永仓（明星仓6号） | G16: 起收重量 | H16: 参考时效开船后 （无赔偿） | I16: 备注
D17: 12KG+ | E17: 50KG+ | F17: 按方包税1CBM+
B18: 一区美西 | C18: POC1/POC3/ POC2 | D18: 4.5 | E18: 3.5 | F18: =E18*200 -> 700 | G18: 12KG+/1CBM+ | H18: 22-28天签收 | I18: 1.我司拒接一切敏感货物，此报价只收普货，如发现冲货，瞒报或者带电不备注行为在我司仓库查到的没收货物并罚款1万-5万元，若因冲货导致海关查验的罚款20万并追究其法律责任，和一切损失 . 2.不同区不可以合并报关(如：一区不能和二区合并报关) 3.按方渠道密度比最高（1CBM：363KGS）
B19: 二区美西 | C19: LGB4/LGB9/LGB6/SBD2 /SNA4/ XLX7/JOT1 | D19: 4.7 | E19: 3.7 | F19: =E19*200 -> 740 | G19: 12KG+/1CBM+ | H19: 22-28天签收
C20: IUSQ/IUSJ/IUSP/IUTI/IUSW/IUTE/PSP3 | D20: 4.7 | E20: 3.7 | F20: =E20*200 -> 740 | G20: 12KG+/1CBM+ | H20: 22-28天签收
B21: 三区美西 | C21: SCK8/MIT2/HLI2/TCY2/TCY1/MCC1 | D21: 5.2 | E21: 4.2 | F21: =E21*200 -> 840 | G21: 12KG+/1CBM+ | H21: 22-28天签收
C22: GEU3/GEU5/GEU2/QXY5/QXY8 | D22: 5.2 | E22: 4.2 | F22: =E22*200 -> 840 | G22: 12KG+/1CBM+ | H22: 22-28天签收
B23: 四区美西 | C23: SJC7/FAT2/SCK1/ MCE1 | D23: 5.2 | E23: 4.2 | F23: =E23*200 -> 840 | G23: 12KG+/1CBM+ | H23: 22-28天签收
C24: PHX5/PHX7/LAS6/OAK3/SMF6 | D24: 5.2 | E24: 4.2 | F24: =E24*200 -> 840 | G24: 12KG+/1CBM+ | H24: 22-28天签收
C25: ABQ2 | D25: 6 | E25: 5 | F25: =E25*200 -> 1000 | G25: 12KG+/1CBM+ | H25: 22-28天签收
B26: 五区美中 | C26: PSC2 | D26: 6.6 | E26: 5.6 | F26: =E26*200 -> 1120 | G26: 12KG+/1CBM+ | H26: 24-30天签收
C27: AMA1/SAT1/SAT4/DFW6/FTW1/IAH3/IUTH/AFW5/FTW5 | D27: 6.8 | E27: 5.8 | F27: =E27*200 -> 1160 | G27: 12KG+/1CBM+ | H27: 24-30天签收
C28: FWA4/IND9/MDW2/IUSF | D28: 7.1 | E28: 6.1 | F28: =E28*200 -> 1220 | G28: 12KG+/1CBM+ | H28: 24-30天签收
C29: MEM1/MQJ1/RFD2/SLC2/BNA6 | D29: 7.1 | E29: 6.1 | F29: =E29*200 -> 1220 | G29: 12KG+/1CBM+ | H29: 24-30天签收
B30: 组合区 | C30: 仓库代码 | D30: 东莞仓(明星仓5号）福永仓（明星仓6号） | G30: 起收重量 | H30: 参考时效开船后 （无赔偿） | I30: 备注
D31: 50KG+ | E31: 100KG+ | F31: 按方包税1CBM+
B32: 六区美中 | C32: BNA2/DEN8/DEN2/FOE1/PPO4 | D32: 7.6 | E32: 6.6 | F32: =E32*200 -> 1320 | G32: 50KG+/1CBM+ | H32: 25-32天左右签收 | I32: 1.我司拒接一切敏感货物，此报价只收普货，如发现冲货，瞒报或者带电不备注行为在我司仓库查到的没收货物并罚款1万-5万元，若因冲货导致海关查验的罚款20万并追究其法律责任，和一切损失 . 2.不同区不可以合并报关(如：一区不能和二区合并报关) 3.按方渠道密度比最高（1CBM：363KGS）
C33: HOU8/ICT2/LIT2/MEM6/MKC4 | D33: 7.6 | E33: 6.6 | F33: =E33*200 -> 1320 | G33: 50KG+/1CBM+ | H33: 25-32天左右签收
C34: OKC2/STL3/STL4/FTW3/BFI3/GEG2 | D34: 7.6 | E34: 6.6 | F34: =E34*200 -> 1320 | G34: 50KG+/1CBM+ | H34: 25-32天左右签收
B35: 七区美中 | C35: CMH2/CMH3/IGQ2/IND2/LAN2 | D35: 7.9 | E35: 6.9 | F35: =E35*200 -> 1380 | G35: 50KG+/1CBM+ | H35: 25-32天左右签收
C36: JVL1/MDW6/ORD2/RFD4/STL6/DET1/DET2 | D36: 7.9 | E36: 6.9 | F36: =E36*200 -> 1380 | G36: 50KG+/1CBM+ | H36: 25-32天左右签收
B37: 组合区 | C37: 仓库代码 | D37: 东莞仓(明星仓5号）福永仓（明星仓6号） | G37: 起收重量 | H37: 参考时效开船后 （无赔偿） | I37: 1.我司拒接一切敏感货物，此报价只收普货，如发现冲货，瞒报或者带电不备注行为在我司仓库查到的没收货物并罚款1万-5万元，若因冲货导致海关查验的罚款20万并追究其法律责任，和一切损失 . 2.不同区不可以合并报关(如：一区不能和二区合并报关) 3.按方渠道密度比最高（1CBM：363KGS）
D38: 12KG+ | E38: 100KG+ | F38: 按方包税1CBM+
B39: 美东纽约专区 | C39: ABE8/AVP1/TEB9/RMN3 | D39: 8.5 | E39: 7.5 | F39: =E39*200 -> 1500 | G39: 12KG+/1CBM+ | H39: 25-32天签收
C40: ACY2/TEB3/TEB6/TTN2/ABE4/RDU4/HEA2/RDU2 | D40: 8.6 | E40: 7.6 | F40: =E40*200 -> 1520 | G40: 12KG+/1CBM+ | H40: 27-35天签收
C41: TEB4/SWF1/SWF2/MDT1/WBW2 | D41: 8.6 | E41: 7.6 | F41: =E41*200 -> 1520 | G41: 12KG+/1CBM+ | H41: 27-35天签收
C42: MDT4/PHL4/PHL5/PHL6/DCA6/ILG1 /IUSL/HIA1 | D42: 8.6 | E42: 7.6 | F42: =E42*200 -> 1520 | G42: 12KG+/1CBM+ | H42: 27-35天签收
C43: ORF2/RIC1/BOS7/ALB1/XLX1/XRI3 | D43: 8.6 | E43: 7.6 | F43: =E43*200 -> 1520 | G43: 12KG+/1CBM+ | H43: 27-35天签收
C44: PIT2/LBE1/CHO1/ AKR1 /IUST | D44: 8.6 | E44: 7.6 | F44: =E44*200 -> 1520 | G44: 12KG+/1CBM+ | H44: 27-35天签收
B45: 组合区 | C45: 仓库代码 | D45: 东莞仓(明星仓5号）福永仓（明星仓6号） | G45: 起收重量 | H45: 参考时效开船后（无赔偿） | I45: 备注
D46: 12KG+ | E46: 100KG+ | F46: 按方包税1CBM+
B47: 美东萨凡纳专区 | C47: CLT2/XAV3 | D47: 8.2 | E47: 7.2 | F47: =E47*200 -> 1440 | G47: 12KG+/1CBM+ | H47: 25-32天签收 | I47: 1.我司拒接一切敏感货物，此报价只收普货，如发现冲货，瞒报或者带电不备注行为在我司仓库查到的没收货物并罚款1万-5万元，若因冲货导致海关查验的罚款20万并追究其法律责任，和一切损失 . 2.不同区不可以合并报关(如：一区不能和二区合并报关) 3.按方渠道密度比最高（1CBM：363KGS）
...

Sheet 华南特惠普船卡派
J3: =目录!H4 -> 明日之星华南价格表入仓执行日期2025/1/27
B4: 浙江明日之星供应链管理有限公司(深圳分公司）
B7: 华南特惠普船直送卡派（SML,HMM,WHL,YMM,TSL,SLS,ONE，CUL)(特惠线渠道有甩柜风险，赶时效货物建议选择OA)
B9: 组合区 | C9: 仓库代码 | D9: 东莞仓(明星仓5号）福永仓（明星仓6号） | G9: 起收重量 | H9: 开船后第二天 开始计算时效签收时效 | I9: 备注
D10: 12KG+ | E10: 50KG+ | F10: 按方包税1CBM+
B11: 洛杉矶特价 | C11: ONT8/LGB8/LAX9/SBD1 | D11: 3.9 | E11: 2.9 | F11: =E11*200 -> 580 | G11: 12KG+/1CBM+ | H11: 21-28天签收 | I11: 此渠道报价为直送柜不接受拦截，若需要拦截每票2200美金/票，不接受合并报关。单件尺寸不超63cm，在截单前到货的保证装走，不集货，不延船期!
C12: GYR2/GYR3/LAS1/SMF3/SCK4/VGT2 | D12: 4.4 | E12: 3.4 | F12: =E12*200 -> 680 | G12: 12KG+/1CBM+ | H12: 21-28天签收
B14: 华南特惠普船卡派（SML,HMM,WHL,YMM,TSL,SLS,ONE，CUL)(特惠线渠道有甩柜风险，赶时效货物建议选择OA)
B16: 组合区 | C16: 仓库代码 | D16: 东莞仓(明星仓5号）福永仓（明星仓6号） | G16: 起收重量 | H16: 参考时效开船后 （无赔偿） | I16: 备注
D17: 12KG+ | E17: 50KG+ | F17: 按方包税1CBM+
B18: 一区美西 | C18: POC1/POC3/ POC2 | D18: 4.2 | E18: 3.2 | F18: =E18*200 -> 640 | G18: 12KG+/1CBM+ | H18: 24-30天签收 | I18: 1.我司拒接一切敏感货物，此报价只收普货，如发现冲货，瞒报或者带电不备注行为在我司仓库查到的没收货物并罚款1万-5万元，若因冲货导致海关查验的罚款20万并追究其法律责任，和一切损失 . 2.不同区不可以合并报关(如：一区不能和二区合并报关) 3.按方渠道密度比最高（1CBM：363KGS）
B19: 二区美西 | C19: LGB4/LGB9/LGB6/SBD2 /SNA4/ XLX7/JOT1 | D19: 4.4 | E19: 3.4 | F19: =E19*200 -> 680 | G19: 12KG+/1CBM+ | H19: 24-30天签收
C20: IUSQ/IUSJ/IUSP/IUTI/IUSW/IUTE/PSP3 | D20: 4.4 | E20: 3.4 | F20: =E20*200 -> 680 | G20: 12KG+/1CBM+ | H20: 24-30天签收
B21: 三区美西 | C21: SCK8/MIT2/HLI2/TCY2/TCY1/MCC1 | D21: 4.9 | E21: 3.9 | F21: =E21*200 -> 780 | G21: 12KG+/1CBM+ | H21: 24-30天签收
C22: GEU3/GEU5/GEU2/QXY5/QXY8 | D22: 4.9 | E22: 3.9 | F22: =E22*200 -> 780 | G22: 12KG+/1CBM+ | H22: 24-30天签收
B23: 四区美西 | C23: SJC7/FAT2/SCK1/ MCE1 | D23: 4.9 | E23: 3.9 | F23: =E23*200 -> 780 | G23: 12KG+/1CBM+ | H23: 24-30天签收
C24: PHX5/PHX7/LAS6/OAK3/SMF6 | D24: 4.9 | E24: 3.9 | F24: =E24*200 -> 780 | G24: 12KG+/1CBM+ | H24: 24-30天签收
C25: ABQ2 | D25: 5.7 | E25: 4.7 | F25: =E25*200 -> 940 | G25: 12KG+/1CBM+ | H25: 24-30天签收
B26: 五区美中 | C26: PSC2 | D26: 6.3 | E26: 5.3 | F26: =E26*200 -> 1060 | G26: 12KG+/1CBM+ | H26: 26-32天签收
C27: AMA1/SAT1/SAT4/DFW6/FTW1/IAH3/IUTH/AFW5/FTW5 | D27: 6.5 | E27: 5.5 | F27: =E27*200 -> 1100 | G27: 12KG+/1CBM+ | H27: 26-32天签收
C28: FWA4/IND9/MDW2/IUSF | D28: 6.8 | E28: 5.8 | F28: =E28*200 -> 1160 | G28: 12KG+/1CBM+ | H28: 26-32天签收
C29: MEM1/MQJ1/RFD2/SLC2/BNA6 | D29: 6.8 | E29: 5.8 | F29: =E29*200 -> 1160 | G29: 12KG+/1CBM+ | H29: 26-32天签收
B30: 组合区 | C30: 仓库代码 | D30: 东莞仓(明星仓5号）福永仓（明星仓6号） | G30: 起收重量 | H30: 参考时效开船后 （无赔偿） | I30: 备注
D31: 50KG+ | E31: 100KG+ | F31: 按方包税1CBM+
B32: 六区美中 | C32: BNA2/DEN8/DEN2/FOE1/PPO4 | D32: 7.3 | E32: 6.3 | F32: =E32*200 -> 1260 | G32: 50KG+/1CBM+ | H32: 27-34天左右签收 | I32: 1.我司拒接一切敏感货物，此报价只收普货，如发现冲货，瞒报或者带电不备注行为在我司仓库查到的没收货物并罚款1000-50000RMB，若因冲货导致海关查验的罚款20万并追究其法律责任，和一切损失 . 2.不同区不可以合并报关(如：一区不能和二区合并报关) 3.按方渠道密度比最高（1CBM：363KGS）
C33: HOU8/ICT2/LIT2/MEM6/MKC4 | D33: 7.3 | E33: 6.3 | F33: =E33*200 -> 1260 | G33: 50KG+/1CBM+ | H33: 27-34天左右签收
C34: OKC2/STL3/STL4/FTW3/BFI3/GEG2 | D34: 7.3 | E34: 6.3 | F34: =E34*200 -> 1260 | G34: 50KG+/1CBM+ | H34: 27-34天左右签收
B35: 七区美中 | C35: CMH2/CMH3/IGQ2/IND2/LAN2 | D35: 7.6 | E35: 6.6 | F35: =E35*200 -> 1320 | G35: 50KG+/1CBM+ | H35: 27-34天左右签收
C36: JVL1/MDW6/ORD2/RFD4/STL6/DET1/DET2 | D36: 7.6 | E36: 6.6 | F36: =E36*200 -> 1320 | G36: 50KG+/1CBM+ | H36: 27-34天左右签收
B37: 组合区 | C37: 仓库代码 | D37: 东莞仓(明星仓5号）福永仓（明星仓6号） | G37: 起收重量 | H37: 参考时效开船后 （无赔偿） | I37: 1.我司拒接一切敏感货物，此报价只收普货，如发现冲货，瞒报或者带电不备注行为在我司仓库查到的没收货物并罚款1万-5万元，若因冲货导致海关查验的罚款20万并追究其法律责任，和一切损失 . 2.不同区不可以合并报关(如：一区不能和二区合并报关) 3.按方渠道密度比最高（1CBM：363KGS）
D38: 12KG+ | E38: 100KG+ | F38: 按方包税1CBM+
B39: 美东纽约专区 | C39: ABE8/AVP1/TEB9/RMN3 | D39: 8.2 | E39: 7.2 | F39: =E39*200 -> 1440 | G39: 12KG+/1CBM+ | H39: 27-36天左右签收
C40: ACY2/TEB3/TEB6/TTN2/ABE4/RDU4/HEA2/RDU2 | D40: 8.3 | E40: 7.3 | F40: =E40*200 -> 1460 | G40: 12KG+/1CBM+ | H40: 27-36天左右签收
C41: TEB4/SWF1/SWF2/MDT1/WBW2 | D41: 8.3 | E41: 7.3 | F41: =E41*200 -> 1460 | G41: 12KG+/1CBM+ | H41: 27-36天左右签收
C42: MDT4/PHL4/PHL5/PHL6/DCA6/ILG1 /IUSL/HIA1 | D42: 8.3 | E42: 7.3 | F42: =E42*200 -> 1460 | G42: 12KG+/1CBM+ | H42: 27-36天左右签收
C43: ORF2/RIC1/BOS7/ALB1/XLX1/XRI3 | D43: 8.3 | E43: 7.3 | F43: =E43*200 -> 1460 | G43: 12KG+/1CBM+ | H43: 27-36天左右签收
C44: PIT2/LBE1/CHO1/ AKR1 /IUST | D44: 8.3 | E44: 7.3 | F44: =E44*200 -> 1460 | G44: 12KG+/1CBM+ | H44: 27-36天左右签收
B45: 组合区 | C45: 仓库代码 | D45: 东莞仓(明星仓5号）福永仓（明星仓6号） | G45: 起收重量 | H45: 参考时效开船后（无赔偿） | I45: 备注
D46: 12KG+ | E46: 100KG+ | F46: 按方包税1CBM+
B47: 美东萨凡纳专区 | C47: CLT2/XAV3 | D47: 7.9 | E47: 6.9 | F47: =E47*200 -> 1380 | G47: 12KG+/1CBM+ | H47: 27-36天左右签收 | I47: 1.我司拒接一切敏感货物，此报价只收普货，如发现冲货，瞒报或者带电不备注行为在我司仓库查到的没收货物并罚款1万-5万元，若因冲货导致海关查验的罚款20万并追究其法律责任，和一切损失 . 2.不同区不可以合并报关(如：一区不能和二区合并报关) 3.按方渠道密度比最高（1CBM：363KGS）
...

Sheet 华南西雅图普船卡派-暂停
B2: 浙江明日之星供应链管理有限公司
B5: 华南西雅图普船卡派（OA,SML统配）-该渠道暂停 对应亚马逊仓库地址建议走洛杉矶港口！！！
G6: =目录!H4 -> 明日之星华南价格表入仓执行日期2025/1/27
B7: 仓库代码 | C7: 东莞仓(明星仓5号）福永仓（明星仓6号） | F7: 起收重量 | G7: 开船后第二天 开始计算时效签收时效 | H7: 备注
C8: 12KG+ | D8: 50KG+ | E8: 按方包税1CBM+
B9: PSC2 | C9: / | D9: / | E9: =D9*200 -> #VALUE! | F9: 12KG+/1CBM+ | G9: 35-40天左右签收 | H9: 此报价只收普货，如发现冲货，瞒报或者带电不备注行为没收货物并罚款10000-50000RMB.
B10: BFI3 | C10: / | D10: / | E10: =D10*200 -> #VALUE! | F10: 12KG+/1CBM+ | G10: 35-40天左右签收
B11: PDX7/PDX6 | C11: / | D11: / | E11: =D11*200 -> #VALUE! | F11: 12KG+/1CBM+ | G11: 35-40天左右签收
B12: GEG2 | C12: / | D12: / | E12: =D12*200 -> #VALUE! | F12: 12KG+/1CBM+ | G12: 35-40天左右签收
B13: 后续关税每上调1%，将对应增加0.03元/kg的费用，按方对应增加6元/方，反之降关税每下调1%，将对应退0.03元/kg的费用，按方对应退6元/方 发货即默认此条款
B14: 50KG+实重比优惠：1:190减0.5、1:250减0.8、1:300减1、1:350减1.3、1:400减1.5、1:450减1.8、1:500及以上减2 比重减后最低1.5/KG
B16: 计费规则
B18: 计费规则：单边超过200CM拒收； 亚马逊地址单件实重超过30KG小于45KG货物加收RMB1/KG； 320CM<一长+两宽+两高<410CM加收5RMB/KG 非亚马逊地址无超重费，超长费正常收取。
B19: 请注意：按照美国海关要求，所有中国出口美国货物的外包装及货物内包装（或者货物本身）必须有“MADE IN CHINA”的标记，否则一旦被查到将会被要求在美国海关的监管下逐件贴标，限期未完成者将会被处以至少为发票金额的6倍的罚款，由此导致的时效延误及一切费用概由客人承担。
B21: 赔偿说明
B23: 1.提供POD 和预约号后 亚马逊的货物请客户在签收后5个工作日内查询限FBA后台是否上架，签收后15个工作日内提供货物未上架后台截图(需带有电脑屏幕右下角当下真实时间)至我司方可进入开查程序，超过20个工作日反馈不予受理和赔偿。若卡派出现丢件在我司规定时间内调查核实后我司予以赔偿。丢件赔偿标准如下： 一.快递派标准 （1） 提取前任何形式的丢件 按货值赔偿（提供货值证明）最高不超过40/kg 不退运费 （2）提取上网后丢件 统一按照每件100美金赔偿 不退运费 二.卡派标准 （包含任何形式的丢件） （1）按公斤计费的丢件 按货值赔偿（提供货值证明）最高不超过40RMB/kg 不退运费 （2）按方计费的丢件 按货值赔偿（提供货值证明）最高不超过600RMB/件 不退运费 2.货物如因自身包装问题造成破损或数量短少的，不作赔偿； 3.货物未如实申报、侵权或不符合当地法规禁止进口的导致海关扣货不作赔偿, 并且保留追究发件人因此带来对我司的损失赔偿责任； 4.因船期延误或清关延误等不可抗因素，不作赔偿； 5.易碎品不接受任何损坏赔偿； 6.如客户一旦交货到我司，则默认上述赔款条例，出货前请详细阅读此赔偿标准。
B25: 注意事项
B27: 1.以上价格为华南仓库交货价,材积货算:长*宽*高CM/6000 。
B28: 3.以上价格为普货产品到最终Amazon仓库的全部价格
B29: 4.可接单独报关件，加收150RMB/票，退税件贸易国只接中国和美国，其他国家或者中国香港无服务。
B30: 5.单票货物超过5个品名，需额外加收30RMB/个。
... B35: 特别提示：如客户一旦交货到我司，我司默认客户已详细阅读此价格表备注内容及说明，并接受其条款的约束！

Sheet 华南奥克兰普船卡派
I2: =目录!H4 -> 明日之星华南价格表入仓执行日期2025/1/27
B3: 浙江明日之星供应链管理有限公司
B6: 华南奥克兰直送卡派（EXX航线和WHL,OA统配）
B8: 渠道产品 | C8: 仓库代码 | E8: 东莞仓(明星仓5号）福永仓（明星仓6号） | H8: 起收重量 | I8: 开船后第二天 开始计算时效签收时效 | J8: 备注
E9: 12KG+ | F9: 50KG+ | G9: 按方包税1CBM+
B10: 奥克兰特惠 | C10: SMF3/SCK4/SJC7/TCY1/TCY2 | E10: 3.8 | F10: 3.3 | G10: =F10*200 -> 660 | H10: 12KG+/1cbm+ | I10: 23-28天左右签收 | J10: 此渠道报价为直送柜不接受拦截，若需要拦截每票2200美金/票，不接受合并报关。单件尺寸不超63cm，在截单前到货的保证装走，不集货，不延船期。
B12: 华南奥克兰拆柜卡派 （EXX航线和WHL,OA统配）
B14: 仓库代码 | D14: 东莞仓(明星仓5号）福永仓（明星仓6号） | G14: 开船后第二天开始计算 | J14: 备注
D15: 12KG+ | E15: 50KG+ | F15: 按方包税1CBM+
B16: MCC1（95742） | D16: 4.1 | E16: 3.6 | F16: =E16*200 -> 720 | G16: 25-30天左右
B17: SCK8（94561） | D17: 4.1 | E17: 3.6 | F17: =E17*200 -> 720 | G17: 25-30天左右
B18: SCK3（95336） | D18: 4.3 | E18: 3.8 | F18: =E18*200 -> 760 | G18: 25-30天左右
B19: OAK3（95363） | D19: 4.3 | E19: 3.8 | F19: =E19*200 -> 760 | G19: 25-30天左右
B20: SCK1（95215） | D20: 4.3 | E20: 3.8 | F20: =E20*200 -> 760 | G20: 25-30天左右
B21: MCE1（95380） | D21: 4.3 | E21: 3.8 | F21: =E21*200 -> 760 | G21: 25-30天左右
B22: SMF6（95835） | D22: 4.5 | E22: 4 | F22: =E22*200 -> 800 | G22: 25-30天左右
B23: HLI2 (95023 ) | D23: 4.5 | E23: 4 | F23: =E23*200 -> 800 | G23: 25-30天左右
B24: SMF7 (95688) | D24: 4.5 | E24: 4 | F24: =E24*200 -> 800 | G24: 25-30天左右
B25: FAT2（93725) | D25: 4.7 | E25: 4.2 | F25: =E25*200 -> 840 | G25: 25-30天左右
B26: SMF1（95688）(沃尔玛） | D26: 4.7 | E26: 4.2 | F26: =E26*200 -> 840 | G26: 25-30天左右
C28: 东莞仓(明星仓5号）福永仓（明星仓6号） | G28: 备注
C29: 50KG+ | D29: 100KG+ | E29: 500KG+ | F29: 按方包税1cbm+
B30: 美西奥克兰海外仓自提 | C30: 4.3 | D30: 3.3 | E30: 3.3 | F30: =D30*200 -> 660 | G30: 出库费$15/托，不包含其他费用（如海外仓仓储费，贴标费，派送费等），如有产生实报实销
B31: 后续关税每上调1%，将对应增加0.03元/kg的费用，按方对应增加6元/方，反之降关税每下调1%，将对应退0.03元/kg的费用，按方对应退6元/方 发货即默认此条款
B32: 50KG+实重比优惠：1:190减0.5、1:250减0.8、1:300减1、1:350减1.3、1:400减1.5、1:450减1.8、1:500及以上减2 比重减后最低1.5/KG
B34: 赔偿说明
B36: 1.提供POD 和预约号后 亚马逊的货物请客户在签收后5个工作日内查询限FBA后台是否上架，签收后15个工作日内提供货物未上架后台截图(需带有电脑屏幕右下角当下真实时间)至我司方可进入开查程序，超过20个工作日反馈不予受理和赔偿。若卡派出现丢件在我司规定时间内调查核实后我司予以赔偿。丢件赔偿标准如下： 一.快递派标准 （1） 提取前任何形式的丢件 按货值赔偿（提供货值证明）最高不超过40/kg 不退运费 （2）提取上网后丢件 统一按照每件100美金赔偿 不退运费 二.卡派标准 （包含任何形式的丢件） （1）按公斤计费的丢件 按货值赔偿（提供货值证明）最高不超过40RMB/kg 不退运费 （2）按方计费的丢件 按货值赔偿（提供货值证明）最高不超过600RMB/件 不退运费 2.货物如因自身包装问题造成破损或数量短少的，不作赔偿； 3.货物未如实申报、侵权或不符合当地法规禁止进口的导致海关扣货不作赔偿, 并且保留追究发件人因此带来对我司的损失赔偿责任； 4.因船期延误或清关延误等不可抗因素，不作赔偿； 5.易碎品不接受任何损坏赔偿； 6.如客户一旦交货到我司，则默认上述赔款条例，出货前请详细阅读此赔偿标准。
B38: 注意事项
B40: 1.以上价格为华南仓库交货价,材积货算:长*宽*高CM/6000 。
B41: 3.以上价格为普货产品到最终Amazon仓库的全部价格
B42: 4.可接单独报关件，加收150RMB/票，退税件贸易国只接中国和美国，其他国家或者中国香港无服务。
B43: 5.单票货物超过5个品名，需额外加收30RMB/个。
B44: 6.订舱需提供出货模块资料，模块资料需提供详细品名，海关编码，材质，用途，图片，地址栏需认真仔细填写。
B45: 7.尺寸及重量：实重30-45KG加收1RMB/KG，(150/方）320CM<一长+两宽+两高<410CM加收5RMB/KG（800/方）尺寸及重量规则均叠加收费
B46: 8.FBA货物每件货物需贴2个或以上合格的FBA标签，我司提供贴标增值服务0.5RMB/标签。
... B48: 特别提示：如客户一旦交货到我司，我司默认客户已详细阅读此价格表备注内容及说明，并接受其条款的约束！

Sheet 华南芝加哥普船卡派
B3: 浙江明日之星供应链管理有限公司
B5: 华南芝加哥直送卡派 （CMA/ZIM/SML/OA统配航线到LA转火车）
H6: =目录!H4 -> 明日之星华南价格表入仓执行日期2025/1/27
B7: 渠道产品 | C7: 仓库代码 | D7: 东莞仓(明星仓5号）福永仓（明星仓6号） | G7: 起收重量 | H7: 开船后第二天 开始计算时效签收时效 | I7: 备注
D8: 12KG+ | E8: 50KG+ | F8: 按方包税1CBM+
B9: 芝加哥特惠卡派 | C9: MDW2 | D9: 6 | E9: 5 | F9: =E9*200 -> 1000 | G9: 12kg+/1CBM+ | H9: 26-31天左右签收 | I9: 此渠道报价为直送柜不接受拦截，若需要拦截每票2200美金/票，不接受合并报关。单件尺寸不超63cm，单件实重不超23kg
C10: IND9/FWA4 | D10: 6.3 | E10: 5.3 | F10: =E10*200 -> 1060 | G10: 12kg+/1CBM+ | H10: 26-31天左右签收
B12: 华南芝加哥普船卡派 （CMA/ZIM/SML/OA统配航线到LA转火车）
B14: 芝加哥一区 | C14: MDW2/ORD2/IGQ2/MDW6 | D14: 6.3 | E14: 5.3 | F14: =E14*200 -> 1060 | G14: 12kg+/1CBM+ | H14: 32-40天左右签收 | I14: 此报价为拆柜派送可以合并，报关此报价只收普货，如发现冲货，瞒报或者带电不备注行为没收货物并罚款1000-50000RMB. 不同区不能合并报关
C15: MDW9/RFD2/RFD4/JVL1/ 沃尔玛---ORD1S | D15: 6.3 | E15: 5.3 | F15: =E15*200 -> 1060 | G15: 12kg+/1CBM+ | H15: 32-40天左右签收
B16: 芝加哥二区 | C16: IND9/MQJ2/STL4/IND2/IND4/IND5/ MQJ1/PPO4/LAN2 | D16: 6.7 | E16: 5.7 | F16: =E16*200 -> 1140 | G16: 12kg+/1CBM+ | H16: 32-40天左右签收
C17: 沃尔玛---IND2/沃尔玛---IND3/沃尔玛---IND2N | D17: 6.8 | E17: 5.8 | F17: =E17*200 -> 1160 | G17: 12kg+/1CBM+ | H17: 32-40天左右签收
B18: 芝加哥三区 | C18: DET1/DET2/CMH2/CMH3/CMH7 | D18: 7 | E18: 6 | F18: =E18*200 -> 1200 | G18: 12kg+/1CBM+ | H18: 32-40天左右签收
B19: 芝加哥四区 | C19: FOE1/MKC4/MCI3/STL3/MEM1/MEM6 | D19: 7.5 | E19: 6.5 | F19: =E19*200 -> 1300 | G19: 12kg+/1CBM+ | H19: 32-40天左右签收
C20: 沃尔玛---KS1/沃尔玛---MCI1N | D20: 7.7 | E20: 6.7 | F20: =E20*200 -> 1340 | G20: 12kg+/1CBM+ | H20: 32-40天左右签收
B21: 芝加哥留仓自提 | C21: 留仓自提 | D21: 6 | E21: 5 | F21: =E21*200 -> 1000 | G21: 12kg+/1CBM+ | H21: 32-40天左右签收
B22: 后续关税每上调1%，将对应增加0.03元/kg的费用，按方对应增加6元/方，反之降关税每下调1%，将对应退0.03元/kg的费用，按方对应退6元/方 发货即默认此条款
B23: 50KG+实重比优惠：1:190减0.5、1:250减0.8、1:300减1、1:350减1.3、1:400减1.5、1:450减1.8、1:500及以上减2 比重减后最低1.5/KG
B25: 计费规则
B27: 计费规则：单边超过200CM拒收； 亚马逊地址单件实重超过30KG小于45KG货物加收RMB1/KG； 320CM<一长+两宽+两高<410CM加收5RMB/KG 非亚马逊地址无超重费，超长费正常收取。
B28: 请注意：按照美国海关要求，所有中国出口美国货物的外包装及货物内包装（或者货物本身）必须有“MADE IN CHINA”的标记，否则一旦被查到将会被要求在美国海关的监管下逐件贴标，限期未完成者将会被处以至少为发票金额的6倍的罚款，由此导致的时效延误及一切费用概由客人承担。
B30: 赔偿说明
B32: 1.提供POD 和预约号后 亚马逊的货物请客户在签收后5个工作日内查询限FBA后台是否上架，签收后15个工作日内提供货物未上架后台截图(需带有电脑屏幕右下角当下真实时间)至我司方可进入开查程序，超过20个工作日反馈不予受理和赔偿。若卡派出现丢件在我司规定时间内调查核实后我司予以赔偿。丢件赔偿标准如下： 一.快递派标准 （1） 提取前任何形式的丢件 按货值赔偿（提供货值证明）最高不超过40/kg 不退运费 （2）提取上网后丢件 统一按照每件100美金赔偿 不退运费 二.卡派标准 （包含任何形式的丢件） （1）按公斤计费的丢件 按货值赔偿（提供货值证明）最高不超过40RMB/kg 不退运费 （2）按方计费的丢件 按货值赔偿（提供货值证明）最高不超过600RMB/件 不退运费 2.货物如因自身包装问题造成破损或数量短少的，不作赔偿； 3.货物未如实申报、侵权或不符合当地法规禁止进口的导致海关扣货不作赔偿, 并且保留追究发件人因此带来对我司的损失赔偿责任； 4.因船期延误或清关延误等不可抗因素，不作赔偿； 5.易碎品不接受任何损坏赔偿； 6.如客户一旦交货到我司，则默认上述赔款条例，出货前请详细阅读此赔偿标准。
B34: 注意事项
B36: 1.以上价格为华南仓库交货价,材积货算:长*宽*高CM/6000 。
B37: 3.以上价格为普货产品到最终Amazon仓库的全部价格
B38: 4.可接单独报关件，加收150RMB/票，退税件贸易国只接中国和美国，其他国家或者中国香港无服务。
B39: 5.单票货物超过5个品名，需额外加收30RMB/个。
... B44: 特别提示：如客户一旦交货到我司，我司默认客户已详细阅读此价格表备注内容及说明，并接受其条款的约束！

Sheet 华南休斯顿普船卡派
H3: =目录!H4 -> 明日之星华南价格表入仓执行日期2025/1/27
B4: 浙江明日之星供应链管理有限公司
B6: 华南休斯顿普船卡派
B8: 渠道产品 | C8: 仓库代码 | D8: 东莞仓(明星仓5号）福永仓（明星仓6号） | G8: 开船后第二天 开始计算时效签收时效 | H8: 备注
D9: 12KG+ | E9: 50KG+ | F9: 按方包税1CBM+
B10: 休斯顿专线拆柜派送 | C10: HOU8/HOU7/HOU3/HOU2/HOU1/IAH3 | D10: 5.1 | E10: 4.1 | F10: =E10*200 -> 820 | G10: 32-40天左右签收 | H10: 此报价为拆柜派送可以合并，报关此报价只收普货，如发现冲货，瞒报或者带电不备注行为没收货物并罚款1000-50000RMB.
C11: FTW9/FTW1/FTW5/FTW3/SAT1/FTW2/IUSF/DFW7/DFW6/DAL3/SAT6/SAT4/IUTH/AFW5 | D11: 5.9 | E11: 4.9 | F11: =E11*200 -> 980 | G11: 32-40天左右签收
C12: MEM6/MEM1/LFT1/AMA1/OKC2/LIT2/ ICT2/FOE1 | D12: 6.5 | E12: 5.5 | F12: =E12*200 -> 1100 | G12: 32-40天左右签收
B13: 休斯顿留仓自提 | D13: 5.1 | E13: 4.1 | F13: =E13*200 -> 820 | G13: 32-40天左右签收
B14: 后续关税每上调1%，将对应增加0.03元/kg的费用，按方对应增加6元/方，反之降关税每下调1%，将对应退0.03元/kg的费用，按方对应退6元/方 发货即默认此条款
B15: 50KG+实重比优惠：1:190减0.5、1:250减0.8、1:300减1、1:350减1.3、1:400减1.5、1:450减1.8、1:500及以上减2 比重减后最低1.5/KG
B17: 计费规则
B19: 计费规则：单边超过200CM拒收； 亚马逊地址单件实重超过30KG小于45KG货物加收RMB1/KG； 320CM<一长+两宽+两高<410CM加收5RMB/KG 非亚马逊地址无超重费，超长费正常收取。
B20: 请注意：按照美国海关要求，所有中国出口美国货物的外包装及货物内包装（或者货物本身）必须有“MADE IN CHINA”的标记，否则一旦被查到将会被要求在美国海关的监管下逐件贴标，限期未完成者将会被处以至少为发票金额的6倍的罚款，由此导致的时效延误及一切费用概由客人承担。
B22: 赔偿说明
B24: 1.提供POD 和预约号后 亚马逊的货物请客户在签收后5个工作日内查询限FBA后台是否上架，签收后15个工作日内提供货物未上架后台截图(需带有电脑屏幕右下角当下真实时间)至我司方可进入开查程序，超过20个工作日反馈不予受理和赔偿。若卡派出现丢件在我司规定时间内调查核实后我司予以赔偿。丢件赔偿标准如下： 一.快递派标准 （1） 提取前任何形式的丢件 按货值赔偿（提供货值证明）最高不超过40/kg 不退运费 （2）提取上网后丢件 统一按照每件100美金赔偿 不退运费 二.卡派标准 （包含任何形式的丢件） （1）按公斤计费的丢件 按货值赔偿（提供货值证明）最高不超过40RMB/kg 不退运费 （2）按方计费的丢件 按货值赔偿（提供货值证明）最高不超过600RMB/件 不退运费 2.货物如因自身包装问题造成破损或数量短少的，不作赔偿； 3.货物未如实申报、侵权或不符合当地法规禁止进口的导致海关扣货不作赔偿, 并且保留追究发件人因此带来对我司的损失赔偿责任； 4.因船期延误或清关延误等不可抗因素，不作赔偿； 5.易碎品不接受任何损坏赔偿； 6.如客户一旦交货到我司，则默认上述赔款条例，出货前请详细阅读此赔偿标准。
B26: 注意事项
B28: 1.以上价格为华南仓库交货价,材积货算:长*宽*高CM/6000 。
B29: 3.以上价格为普货产品到最终Amazon仓库的全部价格
B30: 4.可接单独报关件，加收150RMB/票，退税件贸易国只接中国和美国，其他国家或者中国香港无服务。
B31: 5.单票货物超过5个品名，需额外加收30RMB/个。
... B36: 特别提示：如客户一旦交货到我司，我司默认客户已详细阅读此价格表备注内容及说明，并接受其条款的约束！

Sheet 华南萨凡纳普船卡派
B3: 浙江明日之星供应链管理有限公司
B4: =目录!H4 -> 明日之星华南价格表入仓执行日期2025/1/27
B5: 华南萨凡纳普船卡派
B7: 仓库代码 | C7: 东莞仓(明星仓5号）福永仓（明星仓5号） | F7: 起收重量 | G7: 开船后第二天 开始计算时效签收时效 | H7: 备注
C8: 12KG+ | D8: 50KG+ | E8: 按方包税1CBM+
B9: XLX6/SAV3/MGE3/CLT2/ JAX3 | C9: 5.3 | D9: 4.3 | E9: =D9*200 -> 860 | F9: 12KG+/1CBM+ | G9: 35-45天左右签收 | H9: 此报价只收普货，如发现冲货，瞒报或者带电不备注行为没收货物并罚款1000-50000RMB.
B10: GSP1/RYY2/IUSR/RDU4/ATL8/MGE1/CLT3/XAV3 | C10: 5.7 | D10: 4.7 | E10: =D10*200 -> 940 | F10: 12KG+/1CBM+ | G10: 35-45天左右签收
B11: GSO1/CLT6/CLT4/RDU2/MCO2 | C11: 6 | D11: 5 | E11: =D11*200 -> 1000 | F11: 12KG+/1CBM+ | G11: 35-45天左右签收
B12: TPA2/TPA3/TPA6/ATL2 | C12: 6 | D12: 5 | E12: =D12*200 -> 1000 | F12: 12KG+/1CBM+ | G12: 35-45天左右签收
B13: CHA2/BNA2/HSV1/HSV2/PBI3 /PBI2/XPB2/BNA6 | C13: 6.3 | D13: 5.3 | E13: =D13*200 -> 1060 | F13: 12KG+/1CBM+ | G13: 35-45天左右签收
B14: MEM8/MQY1/TMB8 | C14: 6.3 | D14: 5.3 | E14: =D14*200 -> 1060 | F14: 12KG+/1CBM+ | G14: 35-45天左右签收
B15: Walmart仓点（仓库代码需填写对应的仓点）
B16: Wal-MCO2/Wal-MEM1s | C16: 6.2 | D16: 5.2 | E16: =D16*200 -> 1040 | F16: 12KG+/1CBM+ | G16: 35-45天左右签收
B17: Wal-ATL3/Wal-Atl2n/Wal-ATL1 | C17: 6.2 | D17: 5.2 | E17: =D17*200 -> 1040 | F17: 12KG+/1CBM+ | G17: 35-45天左右签收
B18: 三方私人仓区（仓库代码需填写对应的仓点）不足350kg按照350kg计费
B19: 仓库代码 | C19: 东莞仓(明星仓5号）福永仓（明星仓6号） | F19: 起收重量 | G19: 开船后第二天 开始计算时效签收时效
C20: 350kg+ | D20: 500KG+ | E20: 按方包税1CBM+
B21: 西邮 WPGA1/西邮 WPGA4 | C21: 5 | D21: 4.8 | E21: =D21*200 -> 960 | F21: 350kg+/2CBM+ | G21: 35-45天左右签收
B22: 谷仓美南1号/谷仓美南2号 | C22: 5 | D22: 4.8 | E22: =D22*200 -> 960 | F22: 350kg+/2CBM+ | G22: 35-45天左右签收
B23: 乐歌SAV仓/TIKTOK GA仓 | C23: 5 | D23: 4.8 | E23: =D23*200 -> 960 | F23: 350kg+/2CBM+ | G23: 35-45天左右签收
B24: 运去哪 GA1号仓/大健云仓 GA/万邑通GA仓 | C24: 5 | D24: 4.8 | E24: =D24*200 -> 960 | F24: 350kg+/2CBM+ | G24: 35-45天左右签收
B25: 留仓自提 | C25: 4.9 | D25: 4.7 | E25: =D25*200 -> 940 | F25: 350kg+/2CBM+ | G25: 35-45天左右签收
B26: 后续关税每上调1%，将对应增加0.03元/kg的费用，按方对应增加6元/方，反之降关税每下调1%，将对应退0.03元/kg的费用，按方对应退6元/方 发货即默认此条款
B27: 50KG+实重比优惠：1:190减0.5、1:250减0.8、1:300减1、1:350减1.3、1:400减1.5、1:450减1.8、1:500及以上减2 比重减后最低1.5/KG
B28: 计费规则
B30: 计费规则：单边超过200CM拒收； 亚马逊地址单件实重超过30KG小于45KG货物加收RMB1/KG； 320CM<一长+两宽+两高<410CM加收5RMB/KG 非亚马逊地址无超重费，超长费正常收取。
B31: 请注意：按照美国海关要求，所有中国出口美国货物的外包装及货物内包装（或者货物本身）必须有“MADE IN CHINA”的标记，否则一旦被查到将会被要求在美国海关的监管下逐件贴标，限期未完成者将会被处以至少为发票金额的6倍的罚款，由此导致的时效延误及一切费用概由客人承担。
B33: 赔偿说明
B35: 1.提供POD 和预约号后 亚马逊的货物请客户在签收后5个工作日内查询限FBA后台是否上架，签收后15个工作日内提供货物未上架后台截图(需带有电脑屏幕右下角当下真实时间)至我司方可进入开查程序，超过20个工作日反馈不予受理和赔偿。若卡派出现丢件在我司规定时间内调查核实后我司予以赔偿。丢件赔偿标准如下： 一.快递派标准 （1） 提取前任何形式的丢件 按货值赔偿（提供货值证明）最高不超过40/kg 不退运费 （2）提取上网后丢件 统一按照每件100美金赔偿 不退运费 二.卡派标准 （包含任何形式的丢件） （1）按公斤计费的丢件 按货值赔偿（提供货值证明）最高不超过40RMB/kg 不退运费 （2）按方计费的丢件 按货值赔偿（提供货值证明）最高不超过600RMB/件 不退运费 2.货物如因自身包装问题造成破损或数量短少的，不作赔偿； 3.货物未如实申报、侵权或不符合当地法规禁止进口的导致海关扣货不作赔偿, 并且保留追究发件人因此带来对我司的损失赔偿责任； 4.因船期延误或清关延误等不可抗因素，不作赔偿； 5.易碎品不接受任何损坏赔偿； 6.如客户一旦交货到我司，则默认上述赔款条例，出货前请详细阅读此赔偿标准。
B37: 注意事项
B39: 1.以上价格为华南仓库交货价,材积货算:长*宽*高CM/6000 。
B40: 3.以上价格为普货产品到最终Amazon仓库的全部价格
B41: 4.可接单独报关件，加收150RMB/票，退税件贸易国只接中国和美国，其他国家或者中国香港无服务。
B42: 5.单票货物超过5个品名，需额外加收30RMB/个。
... B47: 特别提示：如客户一旦交货到我司，我司默认客户已详细阅读此价格表备注内容及说明，并接受其条款的约束！

Sheet 华南纽约经济普船卡派
F2: =目录!H4 -> 明日之星华南价格表入仓执行日期2025/1/27
B3: 浙江明日之星供应链管理有限公司(深圳分公司）
B6: 华南纽约经济普船卡派（ZIM-ZXB）
B8: 仓库代码 | C8: 东莞仓(明星仓5号）福永仓（明星仓6号） | F8: 起收重量 | G8: 开船后第二天 开始计算时效签收时效 | H8: 备注
C9: 12KG+ | D9: 50KG+ | E9: 按方包税1CBM+
B10: 特价仓库 ABE8/TEB9/ACY2 | C10: 4.9 | D10: 3.9 | E10: =D10*200 -> 780 | F10: 12kg+/1CBM | G10: 42-48天左右签收 | H10: 此报价只收普货，如发现冲货，瞒报或者带电不备注行为没收货物并罚款1000-50000RMB.
B11: 特价仓库 AVP1/TEB4 | C11: 5.1 | D11: 4.1 | E11: =D11*200 -> 820 | F11: 12kg+/1CBM | G11: 42-48天左右签收
B12: 特价仓库 ORF2/BOS7/RMN3 | C12: 5.8 | D12: 4.8 | E12: =D12*200 -> 960 | F12: 12kg+/1CBM | G12: 42-48天左右签收
B13: TEB3/TEB6/TTN2/ABE4/XEW5 | C13: 5.1 | D13: 4.1 | E13: =D13*200 -> 820 | F13: 12kg+/1CBM | G13: 42-48天左右签收
B14: SWF1//MDT1/WBW2/HEA2 | C14: 5.4 | D14: 4.4 | E14: =D14*200 -> 880 | F14: 12kg+/1CBM | G14: 42-48天左右签收
B15: MDT4/PHL4/PHL5/PHL6/DCA6/ILG1/SWF2 /IUSL/HIA1 | C15: 5.7 | D15: 4.7 | E15: =D15*200 -> 940 | F15: 12kg+/1CBM | G15: 42-48天左右签收
B16: RIC1/ALB1/XLX1/XRI3/ BWI4 | C16: 6.1 | D16: 5.1 | E16: =D16*200 -> 1020 | F16: 12kg+/1CBM | G16: 42-48天左右签收
B17: PIT2/CMH2/CMH3/LBE1/CHO1/AKR1 /IUST | C17: 6.3 | D17: 5.3 | E17: =D17*200 -> 1060 | F17: 12kg+/1CBM | G17: 42-48天左右签收
B18: 留仓自提 | C18: / | D18: 4.1 | E18: =D18*200 -> 820 | F18: 12kg+/1CBM | G18: 42-48天左右签收
B19: 后续关税每上调1%，将对应增加0.03元/kg的费用，按方对应增加6元/方，反之降关税每下调1%，将对应退0.03元/kg的费用，按方对应退6元/方 发货即默认此条款
B20: 50KG+实重比优惠：1:190减0.5、1:250减0.8、1:300减1、1:350减1.3、1:400减1.5、1:450减1.8、1:500及以上减2 比重减后最低1.5/KG
B22: 计费规则
B24: 计费规则：单边超过200CM拒收； 亚马逊地址单件实重超过30KG小于45KG货物加收RMB1/KG； 320CM<一长+两宽+两高<410CM加收5RMB/KG 非亚马逊地址无超重费，超长费正常收取。
B25: 请注意：按照美国海关要求，所有中国出口美国货物的外包装及货物内包装（或者货物本身）必须有“MADE IN CHINA”的标记，否则一旦被查到将会被要求在美国海关的监管下逐件贴标，限期未完成者将会被处以至少为发票金额的6倍的罚款，由此导致的时效延误及一切费用概由客人承担。
B27: 赔偿说明
