Workbook

Sheet 模板(版本20251230)
A1: 客户订单号 | B1: FBA198W1881X | E1: 带电* | F1: 否
A2: 服务* | B2: 丰速达20T卡派 | E2: 带磁* | F2: 否
A3: 地址库编码 | B3: MCC1 | E3: 液体* | F3: 否
A4: 收件人姓名* | B4: =IFERROR(VLOOKUP(B3,地址库!A1:$N$628,3,FALSE),"仓库代码无效，如是非亚马逊地址，删除所有公式后填写") | E4: 粉末* | F4: 否
A5: 收件人公司 | E5: 危险品* | F5: 否
A6: 收件人地址一* | B6: =VLOOKUP(B3,地址库!A1:$N$628,8,FALSE) | E6: 报关方式* | F6: 买单报关
A7: 收件人地址二 | E7: 清关方式 | F7: 一般贸易清关
A8: 收件人地址三 | E8: 交税方式 | F8: 包税
A9: 收件人城市* | B9: =VLOOKUP(B3,地址库!A1:$N$628,11,FALSE) | E9: 交货条款
A10: 收件人省份/州 | B10: =VLOOKUP(B3,地址库!A1:$N$628,12,FALSE) | E10: VAT号*
A11: 收件人邮编* | B11: =VLOOKUP(B3,地址库!A1:$N$628,14,FALSE) | E11: 参考号一
A12: 收件人国家代码(二字代码)* | B12: =VLOOKUP(B3,地址库!A1:$N$628,13,FALSE) | E12: 申报币种** | F12: 美元
A13: 收件人电话 | E13: 备注* | J13: 填入开船时间 | K13: 预计送仓天数 | L13: 预计送仓时间
A14: 收件人邮箱 | E14: 亚马逊预约配送时段* （必填） | J14: 年/月/日 | K14: =VLOOKUP(B2&B3,预计送仓数据!A1:$E$1000,4,FALSE) | L14: =K14+J14
A15: 所在货站 | B15: 深圳坂田仓库 | E15: 亚马逊上架总数量* （必填）
A16: 箱数* | B16: 1
A17: 货箱编号* | B17: PO Number* | C17: 货箱重量(KG) | D17: 货箱长度(CM) | E17: 货箱宽度(CM) | F17: 货箱高度(CM) | G17: 产品英文品名* | H17: 产品中文品名* | I17: 产品申报单价* | J17: 产品申报数量* （单箱产品个数） | K17: 产品材质* | L17: 产品海关编码* | M17: 产品用途* | N17: 产品品牌* | O17: 产品型号* | P17: 产品图片* | Q17: 产品销售链接*
A18: FBA198W1881XU000001-1 | B18: 1CNUE1YS | C18: 18.5 | D18: 1 | E18: 1 | F18: 1 | G18: nylon web belt | H18: 尼龙腰带 | I18: 3 | J18: 56 | K18: Nylon + alloy | L18: 6217.10.9530 | M18: wear | N18: N/A | O18: N/A | P18: 1 | Q18: 1

Sheet 报关方式
A1: 买单报关
A2: 报关退税
A3: 普通报关
A4: 9710
A5: 9810

Sheet 发货渠道
A1: 渠道名称 | B1: 板块
A2: 丰速达16T卡派 | B2: 美国海运
A3: 丰速达16T自税卡派 | B3: 美国海运
A4: 丰速达16T快递派 | B4: 美国海运
A5: 丰速达18T卡派 | B5: 美国海运
A6: 丰速达18T自税卡派 | B6: 美国海运
A7: 丰速达18T快递派 | B7: 美国海运
A8: 丰速达20T卡派 | B8: 美国海运
A9: 丰速达20T自税卡派 | B9: 美国海运
A10: 丰速达20T快递派 | B10: 美国海运
A11: 普船特惠卡派 | B11: 美国海运
A12: 纽约普船卡派 | B12: 美国海运
... A95: 墨西哥双清包税卡派 | B95: 墨西哥

Sheet 地址库
A1: 美国亚马逊地址
A2: 地址简称* | B2: 地址编码* | C2: FBA仓库代码 | D2: 联系人* | E2: 公司名 | F2: 联系电话 | G2: 联系手机 | H2: 地址一* | I2: 地址二 | J2: 地址三 | K2: 城市* | L2: 省/洲 | M2: 国家* | N2: 邮编*
A3: TEB9 | B3: TEB9 | C3: TEB9 | D3: TEB9 | E3: Amazon | F3: 1234567890 | H3: 601 Randolph Road | K3: SOMERSET | L3: NJ | M3: US | N3: 08873
A4: LGA9 | B4: LGA9 | C4: LGA9 | D4: LGA9 | E4: Amazon | F4: 1234567890 | H4: 2170 Route 27 | K4: Edison | L4: NJ | M4: US | N4: 08817
A5: EL96 | B5: EL96 | C5: EL96 | D5: EL96 | E5: Amazon | F5: 1234567890 | H5: 10 sigle lane, unit b | K5: Dayton | L5: NJ | M5: US | N5: 08810
A6: EWR4 | B6: EWR4 | C6: EWR4 | D6: EWR4 | E6: Amazon | F6: 1234567890 | H6: 50 New Canton Way | K6: Robbinsville | L6: NJ | M6: US | N6: 08691
A7: ABE8-401 | B7: ABE8-401 | C7: ABE8-401 | D7: ABE8-401 | E7: Amazon | F7: 1234567890 | H7: 401 Independence Road | K7: Florence | L7: NJ | M7: US | N7: 08518
A8: ABE8-309 | B8: ABE8-309 | C8: ABE8-309 | D8: ABE8-309 | E8: Amazon | F8: 1234567890 | H8: 309 Cedar Lane | K8: Florence | L8: NJ | M8: US | N8: 08518
A9: ABE8 | B9: ABE8 | C9: ABE8 | D9: ABE8 | E9: Amazon | F9: 1234567890 | H9: 401 Independence Road | K9: Florence | L9: NJ | M9: US | N9: 08518
A10: TEB6 | B10: TEB6 | C10: TEB6 | D10: TEB6 | E10: Amazon | F10: 1234567890 | H10: 22 Hightstown Cranbury State Road | K10: Cranbury | L10: NJ | M10: US | N10: 08512
A11: TTN2 | B11: TTN2 | C11: TTN2 | D11: TTN2 | E11: Amazon | F11: 1234567890 | H11: 343 HALF ACRE RD | K11: CRANBURY | L11: NJ | M11: US | N11: 08512
A12: TEB3 | B12: TEB3 | C12: TEB3 | D12: TEB3 | E12: Amazon | F12: 1234567890 | H12: 2651 Oldmans Creek Rd | K12: Logan Township | L12: NJ | M12: US | N12: 08085
A13: IVSD | B13: IVSD | C13: IVSD | D13: IVSD | E13: Amazon | F13: 1234567890 | H13: UNO - Swedesboro NJ 800 Arlington Blvd Swedesboro | K13: Swedesboro | L13: NJ | M13: US | N13: 08085
A14: TEB4 | B14: TEB4 | C14: TEB4 | D14: TEB4 | E14: Amazon | F14: 1234567890 | H14: 747 COURSES LANDING RD | K14: PENNS GROVE | L14: NJ | M14: US | N14: 08069
... A135: FTW9 | B135: FTW9 | C135: FTW9 | D135: FTW9 | E135: Amazon | F135: 1234567890 | H135: 944 West Sandy Lake Road | K135: COPPELL | L135: TX | M135: US | N135: 75019
A136: TUL2 | B136: TUL2 | C136: TUL2 | D136: TUL2 | E136: Amazon | H136: 4040 N 125th E Ave | K136: Tulsa | L136: OK | M136: US | N136: 74116
A137: OKC1 | B137: OKC1 | C137: OKC1 | D137: OKC1 | E137: Amazon | F137: 1234567890 | H137: 9201 S Portland Avenue | K137: OKLAHOMA CITY | L137: OK | M137: US | N137: 73159
A138: OKC2 | B138: OKC2 | C138: OKC2 | D138: OKC2 | E138: Amazon | F138: 1234567890 | H138: 8991 S Portland Avenue | K138: OKLAHOMA CITY | L138: OK | M138: US | N138: 73159
A139: LIT2 | B139: LIT2 | C139: LIT2 | D139: LIT2 | E139: Amazon | F139: 1234567890 | H139: 13001 HIGHWAY 70 | K139: North Little Rock | L139: AR | M139: US | N139: 72117
A140: LFT1 | B140: LFT1 | C140: LFT1 | D140: LFT1 | E140: Amazon | F140: 1234567890 | H140: 3550 NE EVANGELINE TRWY | K140: CARENCRO | L140: LA | M140: US | N140: 70520
A141: TUL1 | B141: TUL1 | C141: TUL1 | D141: TUL1 | E141: Amazon | F141: 1234567890 | H141: 2654 North Highway 169 | K141: Coffeyville | L141: KS | M141: US | N141: 67337
A142: ICT2 | B142: ICT2 | C142: ICT2 | D142: ICT2 | E142: Amazon | F142: 1234567890 | H142: 7130 N BROADWAY AVE | K142: PARK CITY | L142: KS | M142: US | N142: 67219
A143: MCI1 | B143: MCI1 | C143: MCI1 | D143: MCI1 | E143: Amazon | F143: 1234567890 | H143: 113th St & Renner Blvd. | K143: Lenexa | L143: KS | M143: US | N143: 66219
A144: FOE1 | B144: FOE1 | C144: FOE1 | D144: FOE1 | E144: Amazon | F144: 1234567890 | H144: 9400 LEAVENWORTH RD | K144: KANSAS CITY | L144: KS | M144: US | N144: 66109
A145: MKC6 | B145: MKC6 | C145: MKC6 | D145: MKC6 | E145: Amazon | F145: 1234567890 | H145: 6925 Riverview Avenue | K145: Kansas City | L145: KS | M145: US | N145: 66102
A146: MKC4 | B146: MKC4 | C146: MKC4 | D146: MKC4 | E146: Amazon | F146: 1234567890 | H146: 19645 Waverly Rd | K146: Edgerton | L146: KS | M146: US | N146: 66021
A147: STL3 | B147: STL3 | C147: STL3 | D147: STL3 | E147: Amazon | F147: 1234567890 | H147: 3200 E SAWYER RD | K147: REPUBLIC | L147: MO | M147: US | N147: 65738
A148: STL8 | B148: STL8 | C148: STL8 | D148: STL8 | E148: Amazon | F148: 1234567890 | H148: 4000 Premier Parkway SAINT PETERS | K148: SAINT PETERS | L148: MO | M148: US | N148: 63376
... A291: GGE7 | B291: GGE7 | C291: GGE7 | D291: GGE7 | E291: Amazon | F291: 1234567890 | H291: Muse Paintbar 329 Greenwich Street | K291: New York | L291: NY | M291: US | N291: 10013
A292: QXY9 | B292: QXY9 | C292: QXY9 | D292: QXY9 | F292: 1234567890 | H292: 36900 W FOURTH ST | K292: BEAUMONT | L292: CA | M292: US | N292: 92223
A293: ORF2-23297 | B293: ORF2-23297 | C293: ORF2-23297 | D293: ORF2-23297 | E293: Amazon.com Services Inc. | F293: 1234567890 | H293: 9603 Coach Road | K293: Richmond | L293: VA | M293: US | N293: 23297
A294: OLM1 | B294: OLM1 | C294: OLM1 | D294: OLM1 | F294: 1234567890 | H294: 3300 HOGUM BAY RD NE | K294: OLYMPIA | L294: WA | M294: US | N294: 98516-3111
A295: MCE1 | B295: MCE1 | C295: MCE1 | D295: MCE1 | F295: 1234567890 | H295: 3200 Fulkerth Road | K295: TURLOCK | L295: CA | M295: US | N295: 95380
A296: VGT2 | B296: VGT2 | C296: VGT2 | D296: VGT2 | F296: 1234567890 | H296: 6401 Howdy Wells Ave | K296: LAS VEGAS | L296: NV | M296: US | N296: 89115
A297: CHO1 | B297: CHO1 | C297: CHO1 | D297: CHO1 | F297: 1234567890 | H297: 32 Trader Rd | K297: Fishersville | L297: VA | M297: US | N297: 22939
A298: MDT4 | B298: MDT4 | C298: MDT4 | D298: MDT4 | F298: 1234567890 | H298: 5125 Commerce Dr | K298: York | L298: PA | M298: US | N298: 17408
A299: AMA1 | B299: AMA1 | C299: AMA1 | D299: AMA1 | F299: 1234567890 | H299: 8590 NE 24th Avenue | K299: AMARILLO | L299: TX | M299: US | N299: 79108
A300: BFL2 | B300: BFL2 | C300: BFL2 | D300: BFL2 | F300: 1234567890 | H300: 4500 Express Ave | K300: Shafter | L300: CA | M300: US | N300: 93263
A301: SWF2 | B301: SWF2 | C301: SWF2 | D301: SWF2 | F301: 1234567890 | H301: 76 Patriot Way | K301: Hopewell Junction | L301: NY | M301: US | N301: 12533
A302: IUSJ | B302: IUSJ | C302: IUSJ | D302: IUSJ | F302: 1234567890 | H302: 6900 West 4th Street | K302: BEAUMONT | L302: CA | M302: US | N302: 92223
...

Sheet 预计送仓数据
B1: 渠道 | C1: FBA仓库代码 | D1: 预计送仓时效 | E1: 区域
A2: =B2&C2 | B2: 丰速达16T卡派 | C2: ONT8 | D2: 16 | E2: 一区
A3: =B3&C3 | B3: 丰速达16T卡派 | C3: LGB8 | D3: 16 | E3: 一区
A4: =B4&C4 | B4: 丰速达16T卡派 | C4: LAX9 | D4: 16 | E4: 一区
A5: =B5&C5 | B5: 丰速达16T卡派 | C5: SBD1 | D5: 16 | E5: 一区
A6: =B6&C6 | B6: 丰速达16T卡派 | C6: POC1 | D6: 16 | E6: 一区
A7: =B7&C7 | B7: 丰速达16T卡派 | C7: POC2 | D7: 16 | E7: 一区
A8: =B8&C8 | B8: 丰速达16T卡派 | C8: POC3 | D8: 16 | E8: 一区
A9: =B9&C9 | B9: 丰速达16T卡派 | C9: IUSP | D9: 16 | E9: 二区
A10: =B10&C10 | B10: 丰速达16T卡派 | C10: IUSQ | D10: 16 | E10: 二区
A11: =B11&C11 | B11: 丰速达16T卡派 | C11: IUSJ | D11: 16 | E11: 二区
A12: =B12&C12 | B12: 丰速达16T卡派 | C12: IUTI | D12: 16 | E12: 二区
A13: =B13&C13 | B13: 丰速达16T卡派 | C13: IUSW | D13: 16 | E13: 二区
... A76: =B76&C76 | B76: 丰速达16T卡派 | C76: RMN3 | D76: 19 | E76: 十区
B78: 渠道 | C78: FBA仓库代码 | D78: 预计送仓时效 | E78: 区域
A79: =B79&C79 | B79: 丰速达20T卡派 | C79: ONT8 | D79: 18 | E79: 一区
A80: =B80&C80 | B80: 丰速达20T卡派 | C80: LGB8 | D80: 18 | E80: 一区
A81: =B81&C81 | B81: 丰速达20T卡派 | C81: LAX9 | D81: 18 | E81: 一区
A82: =B82&C82 | B82: 丰速达20T卡派 | C82: SBD1 | D82: 18 | E82: 一区
A83: =B83&C83 | B83: 丰速达20T卡派 | C83: POC1 | D83: 18 | E83: 一区
A84: =B84&C84 | B84: 丰速达20T卡派 | C84: POC2 | D84: 18 | E84: 一区
A85: =B85&C85 | B85: 丰速达20T卡派 | C85: POC3 | D85: 18 | E85: 一区
A86: =B86&C86 | B86: 丰速达20T卡派 | C86: IUSP | D86: 18 | E86: 二区
A87: =B87&C87 | B87: 丰速达20T卡派 | C87: IUSQ | D87: 18 | E87: 二区
A88: =B88&C88 | B88: 丰速达20T卡派 | C88: IUSJ | D88: 18 | E88: 二区
A89: =B89&C89 | B89: 丰速达20T卡派 | C89: IUTI | D89: 18 | E89: 二区
A90: =B90&C90 | B90: 丰速达20T卡派 | C90: IUSW | D90: 18 | E90: 二区
... A153: =B153&C153 | B153: 丰速达20T卡派 | C153: RMN3 | D153: 21 | E153: 十区
B155: 渠道 | C155: FBA仓库代码 | D155: 预计送仓时效 | E155: 区域
A156: =B156&C156 | B156: 美森CLX正班卡派 | C156: ONT8 | D156: 15 | E156: 一区
A157: =B157&C157 | B157: 美森CLX正班卡派 | C157: LGB8 | D157: 15 | E157: 一区
A158: =B158&C158 | B158: 美森CLX正班卡派 | C158: LAX9 | D158: 15 | E158: 一区
A159: =B159&C159 | B159: 美森CLX正班卡派 | C159: SBD1 | D159: 15 | E159: 一区
A160: =B160&C160 | B160: 美森CLX正班卡派 | C160: POC1 | D160: 15 | E160: 一区
A161: =B161&C161 | B161: 美森CLX正班卡派 | C161: POC2 | D161: 15 | E161: 一区
A162: =B162&C162 | B162: 美森CLX正班卡派 | C162: POC3 | D162: 15 | E162: 一区
A163: =B163&C163 | B163: 美森CLX正班卡派 | C163: IUSP | D163: 15 | E163: 二区
A164: =B164&C164 | B164: 美森CLX正班卡派 | C164: IUSQ | D164: 15 | E164: 二区
A165: =B165&C165 | B165: 美森CLX正班卡派 | C165: IUSJ | D165: 15 | E165: 二区
A166: =B166&C166 | B166: 美森CLX正班卡派 | C166: IUTI | D166: 15 | E166: 二区
...
